Workbook

Sheet General settings
A2: IMPOSTAZIONI GENERALI
A3: Inizio giornata sabato | C3: 0.375
A4: Durata ciclo | C4: 23 | D4: minuti
A5: Inizio semifinali | C5: 0.375
A6: Inizio finali | C6: 0.4375

Sheet 4x4 MIX
A1: Category: | B1: 4x4 MIX
B3: TEAM | C3: PLAYERS | J3: AGENCY
B4: EUIPO 5 | C4: CSENKE JUDIT | D4: BILLERAULT AURELIEN | E4: CORRADO ALESSANDRO | F4: GURRIERI ROSARIO | G4: ROMERO JULIAN | H4: Federica Foti | J4: EUIPO
B5: Dandy Dandelions | C5: Anna Sofia Messeri | D5: Natalia Alberska | E5: Radovan Kyselica | F5: Oliver Bosnar | G5: Mateusz Rudzik | J5: FRONTEX
B6: Aperol | C6: Monika Ciesielska | D6: Evgenia Kalogeropoulou | E6: Filipe Paisana | F6: Jakub Banka | G6: Claudiu Chirias | H6: Georgios Dimitropoulos | J6: FRONTEX
B7: Ferwanek | C7: Aleksandra Wajda | D7: Federica Ferrari | E7: Damian Krzak | F7: Dariusz Neuhoff von der Ley | G7: Jori Tyni | J7: FRONTEX
B8: Sometimes maybe good | C8: Seixas Joao | D8: Conti Lucia | E8: Klayn Aglika | F8: Bonato Stefano | G8: Rausch Laura | J8: EUROJUST
B9: EFSA 6 | C9: Kralova Irena | D9: Pecoraro Simona | E9: Marchese Emanuela | F9: Marchesini Matteo | G9: Ackerl Reinhard | H9: Ferri Alessandro | J9: EFSA
B10: House of Medici | C10: Mihaela Pereteatcu | D10: Valentina Cordo | E10: Thibaut Sauces | F10: Frank Pétavy | G10: Evangelos Kotzagiorgis | H10: Caroline Pothet | J10: EMA
B11: EUAA Comets | C11: Tania | D11: Claudia | E11: Vasileios | F11: Daniela | G11: Maria | J11: EUAA
B12: Mela Blinders | C12: Filothei | D12: Anna Isabel | E12: Raquel | F12: Wade | G12: Valeria | J12: EUAA
B13: EUROPOL 4 MIX | C13: Stanciu Anca | D13: Serra Jose Manuel de Jesus | E13: Ciprian Istudor | F13: Federica C. | J13: EUROPOL
B14: Horizon setters | C14: Piiroja Ivi | D14: ANTONELLI Margherita | E14: Deniz Javier | F14: Napolitano Andrea | J14: REA
B15: REALL | C15: Scioni Barbara | D15: Medarova Keti | E15: Paunovic Ogren | F15: Amedja Ecki | J15: REA
B16: Che fastidio | C16: Michela | D16: Silvio | E16: Flavio | F16: Elisa B. | J16: JRC
B17: Sand by me | C17: Daniele | D17: Fabio | E17: Roberto | F17: Federica R. | G17: Ilaria | J17: JRC
B18: Upsand Down | C18: Tom | D18: Mauro Gabbarini | E18: Federica Ferretti | F18: Diana | G18: Boba | H18: Giovanni | J18: JRC
A20: =+COUNTA(B4:B18) -> 15
A21: Groups
A22: A | B22: B | C22: C | D22: D | E22: E
A23: =+B4 -> EUIPO 5 | B23: =+B5 -> Dandy Dandelions | C23: =+B6 -> Aperol | D23: =+B7 -> Ferwanek | E23: =+B8 -> Sometimes maybe good
A24: =+B9 -> EFSA 6 | B24: =+B10 -> House of Medici | C24: =+B11 -> EUAA Comets | D24: =+B12 -> Mela Blinders | E24: =+B13 -> EUROPOL 4 MIX
A25: =+B14 -> Horizon setters | B25: =+B15 -> REALL | C25: =+B16 -> Che fastidio | D25: =+B17 -> Sand by me | E25: =+B18 -> Upsand Down
C27: Calendar | H27: Referee | I27: Score
A28: Torneo | B28: Group | C28: Team1 | D28: Team 2 | E28: Court | F28: Date | G28: Time
A29: 4x4Mix | B29: C | C29: =+C23 -> Aperol | D29: =+C24 -> EUAA Comets | E29: 3 | F29: 46186 | G29: ='General settings'!C$3 -> 0.375 | H29: =+D34 -> Che fastidio
A30: 4x4Mix | B30: B | C30: =+B23 -> Dandy Dandelions | D30: =+B24 -> House of Medici | E30: 4 | F30: 46186 | G30: ='General settings'!C$3 -> 0.375 | H30: =+D35 -> REALL
A31: 4x4Mix | B31: A | C31: =+A23 -> EUIPO 5 | D31: =+A24 -> EFSA 6 | E31: 1 | F31: 46186 | G31: ='General settings'!C$3 -> 0.375 | H31: =+D36 -> Horizon setters
A32: 4x4Mix | B32: D | C32: =+D23 -> Ferwanek | D32: =+D24 -> Mela Blinders | E32: 2 | F32: 46186 | G32: ='General settings'!C$3 -> 0.375 | H32: =+D37 -> Sand by me
A33: 4x4Mix | B33: E | C33: =+E23 -> Sometimes maybe good | D33: =+E24 -> EUROPOL 4 MIX | E33: 3 | F33: 46186 | G33: =G29+'General settings'!C$4/1440 -> 0.39097222 | H33: =+D38 -> Upsand Down
A34: 4x4Mix | B34: C | C34: =+C24 -> EUAA Comets | D34: =+C25 -> Che fastidio | E34: 4 | F34: 46186 | G34: =G30+'General settings'!C$4/1440 -> 0.39097222 | H34: =+C39 -> Aperol
A35: 4x4Mix | B35: B | C35: =+B24 -> House of Medici | D35: =+B25 -> REALL | E35: 1 | F35: 46186 | G35: =G31+'General settings'!C$4/1440 -> 0.39097222 | H35: =+C40 -> Dandy Dandelions
A36: 4x4Mix | B36: A | C36: =+A24 -> EFSA 6 | D36: =+A25 -> Horizon setters | E36: 2 | F36: 46186 | G36: =G32+'General settings'!C$4/1440 -> 0.39097222 | H36: =+C41 -> EUIPO 5
A37: 4x4Mix | B37: D | C37: =+D24 -> Mela Blinders | D37: =+D25 -> Sand by me | E37: 3 | F37: 46186 | G37: =G33+'General settings'!C$4/1440 -> 0.40694444 | H37: =+C42 -> Ferwanek
A38: 4x4Mix | B38: E | C38: =+E24 -> EUROPOL 4 MIX | D38: =+E25 -> Upsand Down | E38: 4 | F38: 46186 | G38: =G34+'General settings'!C$4/1440 -> 0.40694444 | H38: =+C43 -> Sometimes maybe good
A39: 4x4Mix | B39: C | C39: =+C23 -> Aperol | D39: =+C25 -> Che fastidio | E39: 1 | F39: 46186 | G39: =G35+'General settings'!C$4/1440 -> 0.40694444 | H39: =+D29 -> EUAA Comets
A40: 4x4Mix | B40: B | C40: =+B23 -> Dandy Dandelions | D40: =+B25 -> REALL | E40: 2 | F40: 46186 | G40: =G36+'General settings'!C$4/1440 -> 0.40694444 | H40: =+D30 -> House of Medici
A41: 4x4Mix | B41: A | C41: =+A23 -> EUIPO 5 | D41: =+A25 -> Horizon setters | E41: 3 | F41: 46186 | G41: =G39+'General settings'!C$4/1440 -> 0.42291667 | H41: =+D31 -> EFSA 6
A42: 4x4Mix | B42: D | C42: =+D23 -> Ferwanek | D42: =+D25 -> Sand by me | E42: 4 | F42: 46186 | G42: =G40+'General settings'!C$4/1440 -> 0.42291667 | H42: =+D32 -> Mela Blinders
A43: 4x4Mix | B43: E | C43: =+E23 -> Sometimes maybe good | D43: =+E25 -> Upsand Down | E43: 1 | F43: 46186 | G43: =G39+'General settings'!C$4/1440 -> 0.42291667 | H43: =+D33 -> EUROPOL 4 MIX
...

Sheet 2x2M
A2: Category: | B2: 2x2 MEN
B4: TEAM | C4: PLAYERS | E4: AGENCY
B5: Europol 2x2 men | C5: Ciprian Istudor | D5: Ionut Sava | E5: EUROPOL
B6: Chill-out | C6: Mateusz Rudzik | D6: Mariusz Dzierżawski | E6: FRONTEX
B7: Ballbreakers | C7: Oliver Bosnar | D7: Michal Narojek | E7: FRONTEX
B8: DP's | C8: Filipe Paisana | D8: Georgios Dimitropoulos | E8: FRONTEX
B9: Dunaj & Wisla | C9: Radovan Kyselica | D9: Dariusz Neuhoff von der Ley | E9: FRONTEX
B10: Bacalhau&porchetta | C10: Seixas Joao | D10: Bonato Stefano | E10: EUROJUST
B11: EFSA 1 | C11: Marchesini Matteo | D11: Ackerl Reinhard | E11: EFSA
B12: EFSA 2 | C12: Ferri Alessandro | D12: Marinelli Andrea | E12: EFSA
B13: I transalpini | C13: Frank Pétavy | D13: Thibaut Sauces | E13: EMA
B14: Beach control | C14: Evangelos Kotzagiorgis | D14: Alex Gentimis | E14: EMA
B15: Valletta's Tritons | C15: Vasileios | D15: Wade | E15: EUAA
B16: Too hot for indoor | C16: Daniele | D16: Carlo | E16: JRC
... B18: JRC 3 | C18: Mauro Gabbarini | D18: Tom | E18: JRC
A20: =+COUNTA(B5:B18) -> 14
A22: Groups
A23: A | B23: B | C23: C | D23: D
A24: =+B16 -> Too hot for indoor | B24: =+B5 -> Europol 2x2 men | C24: =+B10 -> Bacalhau&porchetta | D24: =+B11 -> EFSA 1
A25: =+B6 -> Chill-out | B25: =+B7 -> Ballbreakers | C25: =+B8 -> DP's | D25: =+B17 -> Que farà Farà
A26: =+B12 -> EFSA 2 | B26: =+B18 -> JRC 3 | C26: =+B13 -> I transalpini | D26: =+B9 -> Dunaj & Wisla
A27: =+B15 -> Valletta's Tritons | B27: =+B14 -> Beach control
C29: Calendar | H29: Referee | I29: Score
A30: Torneo | B30: Group | C30: Team1 | D30: Team 2 | E30: Court | F30: Date | G30: Time
A31: 2x2M | B31: A | C31: =+A24 -> Too hot for indoor | D31: =+A25 -> Chill-out | E31: 1 | F31: 46186 | G31: ='4x4 MIX'!G44+'General settings'!C$4/1440 -> 0.45486111 | H31: =+A27 -> Valletta's Tritons
A32: 2x2M | B32: B | C32: =+B24 -> Europol 2x2 men | D32: =+B25 -> Ballbreakers | E32: 2 | F32: 46186 | G32: ='4x4 MIX'!G45+'General settings'!C$4/1440 -> 0.45486111 | H32: =+C36 -> JRC 3
A33: 2x2M | B33: C | C33: =+C24 -> Bacalhau&porchetta | D33: =+C25 -> DP's | E33: 1 | F33: 46186 | G33: =G31+'General settings'!C$4/1440 -> 0.47083333 | H33: =+D37 -> I transalpini
A34: 2x2M | B34: D | C34: =+D24 -> EFSA 1 | D34: =+D25 -> Que farà Farà | E34: 2 | F34: 46186 | G34: =G32+'General settings'!C$4/1440 -> 0.47083333 | H34: =+D38 -> Dunaj & Wisla
A35: 2x2M | B35: A | C35: =+A24 -> Too hot for indoor | D35: =+A26 -> EFSA 2 | E35: 1 | F35: 46186 | G35: =G33+'General settings'!C$4/1440 -> 0.48680556 | H35: =+D31 -> Chill-out
A36: 2x2M | B36: B | C36: =+B26 -> JRC 3 | D36: =+B27 -> Beach control | E36: 2 | F36: 46186 | G36: =G34+'General settings'!C$4/1440 -> 0.48680556 | H36: =+C40 -> Europol 2x2 men
A37: 2x2M | B37: C | C37: =+C25 -> DP's | D37: =+C26 -> I transalpini | E37: 1 | F37: 46186 | G37: =G35+'General settings'!C$4/1440 -> 0.50277778 | H37: =+C41 -> Bacalhau&porchetta
A38: 2x2M | B38: D | C38: =+D25 -> Que farà Farà | D38: =+D26 -> Dunaj & Wisla | E38: 2 | F38: 46186 | G38: =G36+'General settings'!C$4/1440 -> 0.50277778 | H38: =+C42 -> EFSA 1
A39: 2x2M | B39: A | C39: =+A26 -> EFSA 2 | D39: =+A27 -> Valletta's Tritons | E39: 1 | F39: 46186 | G39: =G37+'General settings'!C$4/1440 -> 0.51875 | H39: =+A24 -> Too hot for indoor
A40: 2x2M | B40: B | C40: =+B24 -> Europol 2x2 men | D40: =+B26 -> JRC 3 | E40: 2 | F40: 46186 | G40: =G38+'General settings'!C$4/1440 -> 0.51875 | H40: =+C44 -> Ballbreakers
A41: 2x2M | B41: C | C41: =+C24 -> Bacalhau&porchetta | D41: =+C26 -> I transalpini | E41: 1 | F41: 46186 | G41: =G39+'General settings'!C$4/1440 -> 0.53472222 | H41: =+D33 -> DP's
A42: 2x2M | B42: D | C42: =+D24 -> EFSA 1 | D42: =+D26 -> Dunaj & Wisla | E42: 2 | F42: 46186 | G42: =G40+'General settings'!C$4/1440 -> 0.53472222 | H42: =+D34 -> Que farà Farà
A43: 2x2M | B43: A | C43: =+A25 -> Chill-out | D43: =+A27 -> Valletta's Tritons | E43: 1 | F43: 46186 | G43: =G41+'General settings'!C$4/1440 -> 0.55069444 | H43: =+C45 -> Too hot for indoor
A44: 2x2M | B44: B | C44: =+B25 -> Ballbreakers | D44: =+B27 -> Beach control | E44: 2 | F44: 46186 | G44: =G42+'General settings'!C$4/1440 -> 0.55069444 | H44: =+C46 -> Europol 2x2 men
A45: 2x2M | B45: A | C45: =+A24 -> Too hot for indoor | D45: =+A27 -> Valletta's Tritons | E45: 1 | F45: 46186 | G45: =G43+'General settings'!C$4/1440 -> 0.56666667 | H45: =+A26 -> EFSA 2
A46: 2x2M | B46: B | C46: =+B24 -> Europol 2x2 men | D46: =+B27 -> Beach control | E46: 2 | F46: 46186 | G46: =G44+'General settings'!C$4/1440 -> 0.56666667 | H46: =+C48 -> Ballbreakers
...

Sheet 2x2F
A2: Category: | B2: 2x2 WOMEN
B4: TEAM | C4: PLAYERS | E4: AGENCY
B5: ITAegean | C5: Evgenia Kalogeropoulou | D5: Anna Sofia Messeri | E5: FRONTEX
B6: MURO ! | C6: Natalia Alberska | D6: Anna Jaroszuk | E6: FRONTEX
B7: FedAle | C7: Aleksandra Wajda | D7: Federica Ferrari | E7: FRONTEX
B8: Nanook | C8: Conti Lucia | D8: Klayn Aglika | E8: EUROJUST
B9: EFSA 7 | C9: Kralova Irena | D9: Pecoraro Simona | E9: EFSA
B10: Blue Lagoon Spritz | C10: Claudia | D10: Tania | E10: EUAA
B11: Pastizzi Patrol | C11: Daniela | D11: Raquel | E11: EUAA
B12: Barrakka Gardeners | C12: Filothei | D12: Maria | E12: EUAA
B13: EUROPOL F | C13: Stanciu Anca | D13: Rausch Laura | E13: EUROPOL
B14: Disaqueens | C14: Boba | D14: Federica R. | E14: JRC
B15: JRC 12 | C15: Elisa B. | D15: Ilaria | E15: JRC
A17: =COUNTA(B5:B15) -> 11
A19: Groups
A20: A | B20: B | C20: C
A21: =+B5 -> ITAegean | B21: =+B6 -> MURO ! | C21: =+B7 -> FedAle
A22: =+B8 -> Nanook | B22: =+B9 -> EFSA 7 | C22: =+B10 -> Blue Lagoon Spritz
A23: =+B11 -> Pastizzi Patrol | B23: =+B12 -> Barrakka Gardeners | C23: =+B13 -> EUROPOL F
A24: =+B14 -> Disaqueens | B24: =+B15 -> JRC 12
D26: Calendar | H26: Referee | I26: Score
A27: Torneo | B27: Group | C27: Team1 | D27: Team 2 | E27: Court | F27: Date | G27: Time
A28: 2x2F | B28: C | C28: =+C21 -> FedAle | D28: =+C22 -> Blue Lagoon Spritz | E28: 3 | F28: 46186 | G28: =MAX('4x4 MIX'!G$29:G$45)+'General settings'!C$4/1440 -> 0.45486111 | H28: =+D33 -> EUROPOL F
A29: 2x2F | B29: B | C29: =+B21 -> MURO ! | D29: =+B22 -> EFSA 7 | E29: 4 | F29: 46186 | G29: =MAX('4x4 MIX'!G$29:G$45)+'General settings'!C$4/1440 -> 0.45486111 | H29: =+C32 -> Barrakka Gardeners
A30: 2x2F | B30: A | C30: =+A21 -> ITAegean | D30: =+A22 -> Nanook | E30: 3 | F30: 46186 | G30: =G28+'General settings'!C$4/1440 -> 0.47083333 | H30: =+C31 -> Pastizzi Patrol
A31: 2x2F | B31: A | C31: =+A23 -> Pastizzi Patrol | D31: =+A24 -> Disaqueens | E31: 4 | F31: 46186 | G31: =G29+'General settings'!C$4/1440 -> 0.47083333 | H31: =+C34 -> ITAegean
A32: 2x2F | B32: B | C32: =+B23 -> Barrakka Gardeners | D32: =+B24 -> JRC 12 | E32: 3 | F32: 46186 | G32: =G30+'General settings'!C$4/1440 -> 0.48680556 | H32: =+C35 -> MURO !
A33: 2x2F | B33: C | C33: =+C21 -> FedAle | D33: =+C23 -> EUROPOL F | E33: 4 | F33: 46186 | G33: =G31+'General settings'!C$4/1440 -> 0.48680556 | H33: =+C37 -> Blue Lagoon Spritz
A34: 2x2F | B34: A | C34: =+A21 -> ITAegean | D34: =+A23 -> Pastizzi Patrol | E34: 3 | F34: 46186 | G34: =G32+'General settings'!C$4/1440 -> 0.50277778 | H34: =+C36 -> Nanook
A35: 2x2F | B35: B | C35: =+B21 -> MURO ! | D35: =+B23 -> Barrakka Gardeners | E35: 4 | F35: 46186 | G35: =G33+'General settings'!C$4/1440 -> 0.50277778 | H35: =+C38 -> EFSA 7
A36: 2x2F | B36: A | C36: =+A22 -> Nanook | D36: =+A24 -> Disaqueens | E36: 3 | F36: 46186 | G36: =G34+'General settings'!C$4/1440 -> 0.51875 | H36: =+C39 -> ITAegean
A37: 2x2F | B37: C | C37: =+C22 -> Blue Lagoon Spritz | D37: =+C23 -> EUROPOL F | E37: 4 | F37: 46186 | G37: =G35+'General settings'!C$4/1440 -> 0.51875 | H37: =+C28 -> FedAle
A38: 2x2F | B38: B | C38: =+B22 -> EFSA 7 | D38: =+B23 -> Barrakka Gardeners | E38: 3 | F38: 46186 | G38: =G36+'General settings'!C$4/1440 -> 0.53472222 | H38: =+D40 -> JRC 12
A39: 2x2F | B39: A | C39: =+A21 -> ITAegean | D39: =+A24 -> Disaqueens | E39: 4 | F39: 46186 | G39: =G37+'General settings'!C$4/1440 -> 0.53472222 | H39: =+C41 -> Nanook
A40: 2x2F | B40: B | C40: =+B21 -> MURO ! | D40: =+B24 -> JRC 12 | E40: 3 | F40: 46186 | G40: =G38+'General settings'!C$4/1440 -> 0.55069444 | H40: =+C42 -> EFSA 7
A41: 2x2F | B41: A | C41: =+A22 -> Nanook | D41: =+A23 -> Pastizzi Patrol | E41: 4 | F41: 46186 | G41: =G39+'General settings'!C$4/1440 -> 0.55069444 | H41: =+D39 -> Disaqueens
A42: 2x2F | B42: B | C42: =+B22 -> EFSA 7 | D42: =+B24 -> JRC 12 | E42: 3 | F42: 46186 | G42: =G40+'General settings'!C$4/1440 -> 0.56666667 | H42: =+C29 -> MURO !
A46: Group winner 1st best ranked team
C47: First finalist
A49: Best second of the groups
...

Sheet 2x2 MIX
A1: Category: | B1: 2x2 MIX
B3: TEAM | C3: PLAYERS | E3: AGENCY
B4: EUIPO 3 | C4: CSENKE JUDIT | D4: BILLERAULT AURELIEN | E4: EUIPO
B5: EUIPO 4 | C5: Federica Foti | D5: CORRADO ALESSANDRO | E5: EUIPO
B6: Copacabana | C6: Michal Narojek | D6: Monika Ciesielska | E6: FRONTEX
B7: Keto | C7: Georgios Dimitropoulos | D7: Evgenia Kalogeropoulou | E7: FRONTEX
B8: Jellybeans | C8: Natalia Alberska | D8: Oliver Bosnar | E8: FRONTEX
B9: Volare oooh | C9: Anna Sofia Messeri | D9: Mariusz Dzierżawski | E9: FRONTEX
B10: ECDC | C10: Ionut Sava | D10: Anna Jaroszuk | E10: ECDC
B11: Paddington | C11: Seixas Joao | D11: Klayn Aglika | E11: EUROJUST
B12: The Lambrusco Paradox | C12: Bonato Stefano | D12: Conti Lucia | E12: EUROJUST
B13: From Tokyo to The Hague | C13: Rausch Laura | D13: Marinelli Andrea | E13: EUROJUST
B14: EFSA 3 | C14: Marchese Emanuela | D14: Marchesini Matteo | E14: EFSA
B15: EFSA 4 | C15: Kralova Irena | D15: Ackerl Reinhard | E15: EFSA
... B28: Ticino e Carbonara | C28: Federica C. | D28: Roberto | E28: JRC
A30: =+COUNTA(B4:B28) -> 25
A32: Groups
A33: A | B33: B | C33: C | D33: D | E33: E | F33: F
A34: =+B4 -> EUIPO 3 | B34: =+B5 -> EUIPO 4 | C34: =+B6 -> Copacabana | D34: =+B7 -> Keto | E34: =+B8 -> Jellybeans | F34: =+B9 -> Volare oooh
A35: =+B11 -> Paddington | B35: =+B12 -> The Lambrusco Paradox | C35: =+B13 -> From Tokyo to The Hague | D35: =+B14 -> EFSA 3 | E35: =+B15 -> EFSA 4 | F35: =+B16 -> EFSA 5
A36: =+B18 -> Ooh la la | B36: =+B19 -> Balkan Beach Ballers | C36: =+B20 -> Mdina Defenders | D36: =+B21 -> Ftira Fellowship | E36: =+B22 -> EUROPOL MIX | F36: =+B23 -> BBB
A37: =+B25 -> Se non spigoli non vale | B37: =+B26 -> JRC Energy dense | C37: =+B27 -> Gianmarcoooo | D37: =+B28 -> Ticino e Carbonara | E37: =+B24 -> Sandstormers | F37: =+B17 -> Sandbox players
A38: =+B10 -> ECDC
C41: Calendar
A42: Torneo | B42: Group | C42: Team1 | D42: Team 2 | E42: Court | F42: Date | G42: Time | H42: Referee | I42: Score
A43: 2x2 Mix | B43: A | C43: =+A34 -> EUIPO 3 | D43: =+A35 -> Paddington | E43: 1 | F43: 46186 | G43: =MAX('2x2M'!G$31:G$48,'2x2F'!G$28:G$42)+'General settings'!C$4/1440 -> 0.59861111 | H43: =+C49 -> Ooh la la
A44: 2x2 Mix | B44: B | C44: =+B34 -> EUIPO 4 | D44: =+B35 -> The Lambrusco Paradox | E44: 2 | F44: 46186 | G44: =MAX('2x2M'!G$31:G$48,'2x2F'!G$28:G$42)+'General settings'!C$4/1440 -> 0.59861111 | H44: =+C50 -> Balkan Beach Ballers
A45: 2x2 Mix | B45: C | C45: =+C34 -> Copacabana | D45: =+C35 -> From Tokyo to The Hague | E45: 3 | F45: 46186 | G45: =MAX('2x2M'!G$31:G$48,'2x2F'!G$28:G$42)+2*'General settings'!C$4/1440 -> 0.61458333 | H45: =+C51 -> Mdina Defenders
A46: 2x2 Mix | B46: D | C46: =+D34 -> Keto | D46: =+D35 -> EFSA 3 | E46: 4 | F46: 46186 | G46: =MAX('2x2M'!G$31:G$48,'2x2F'!G$28:G$42)+2*'General settings'!C$4/1440 -> 0.61458333 | H46: =+C52 -> Ftira Fellowship
A47: 2x2 Mix | B47: E | C47: =+E34 -> Jellybeans | D47: =+E35 -> EFSA 4 | E47: 1 | F47: 46186 | G47: =G43+'General settings'!C$4/1440 -> 0.61458333 | H47: =+C53 -> EUROPOL MIX
A48: 2x2 Mix | B48: F | C48: =+F34 -> Volare oooh | D48: =+F35 -> EFSA 5 | E48: 2 | F48: 46186 | G48: =G44+'General settings'!C$4/1440 -> 0.61458333 | H48: =+C54 -> BBB
A49: 2x2 Mix | B49: A | C49: =+A36 -> Ooh la la | D49: =+A37 -> Se non spigoli non vale | E49: 3 | F49: 46186 | G49: =G45+'General settings'!C$4/1440 -> 0.63055556 | H49: =+D55 -> ECDC
A50: 2x2 Mix | B50: B | C50: =+B36 -> Balkan Beach Ballers | D50: =+B37 -> JRC Energy dense | E50: 4 | F50: 46186 | G50: =G46+'General settings'!C$4/1440 -> 0.63055556 | H50: =+C56 -> EUIPO 4
A51: 2x2 Mix | B51: C | C51: =+C36 -> Mdina Defenders | D51: =+C37 -> Gianmarcoooo | E51: 1 | F51: 46186 | G51: =G47+'General settings'!C$4/1440 -> 0.63055556 | H51: =+C57 -> Copacabana
A52: 2x2 Mix | B52: D | C52: =+D36 -> Ftira Fellowship | D52: =+D37 -> Ticino e Carbonara | E52: 2 | F52: 46186 | G52: =G48+'General settings'!C$4/1440 -> 0.63055556 | H52: =+C58 -> Keto
A53: 2x2 Mix | B53: E | C53: =+E36 -> EUROPOL MIX | D53: =+E37 -> Sandstormers | E53: 3 | F53: 46186 | G53: =G49+'General settings'!C$4/1440 -> 0.64652778 | H53: =+C59 -> Jellybeans
A54: 2x2 Mix | B54: F | C54: =+F36 -> BBB | D54: =+F37 -> Sandbox players | E54: 4 | F54: 46186 | G54: =G50+'General settings'!C$4/1440 -> 0.64652778 | H54: =+C60 -> Volare oooh
A55: 2x2 Mix | B55: A | C55: =+A34 -> EUIPO 3 | D55: =+A38 -> ECDC | E55: 1 | F55: 46186 | G55: =G51+'General settings'!C$4/1440 -> 0.64652778 | H55: =+C61 -> Paddington
A56: 2x2 Mix | B56: B | C56: =+B34 -> EUIPO 4 | D56: =+B36 -> Balkan Beach Ballers | E56: 2 | F56: 46186 | G56: =G52+'General settings'!C$4/1440 -> 0.64652778 | H56: =+C62 -> The Lambrusco Paradox
A57: 2x2 Mix | B57: C | C57: =+C34 -> Copacabana | D57: =+C36 -> Mdina Defenders | E57: 3 | F57: 46186 | G57: =G53+'General settings'!C$4/1440 -> 0.6625 | H57: =+C63 -> From Tokyo to The Hague
...

Sheet Global
J3: Team 1 players | P3: Team 2 players
A4: Torneo | B4: Group | C4: Team1 | D4: Team 2 | E4: Court | F4: Date | G4: Time | H4: team 1 agency | I4: team 2 agency | J4: Giocatore 1 | K4: Giocatore 2 | L4: Giocatore 3 | M4: Giocatore 4 | N4: Giocatore 5 | O4: Giocatore 6 | P4: Giocatore 7 | Q4: Giocatore 8 | R4: Giocatore 9 | S4: Giocatore 10 | T4: Giocatore 11 | U4: Giocatore 12
A5: =+'4x4 MIX'!A29 -> 4x4Mix | B5: =+'4x4 MIX'!B29 -> C | C5: =+'4x4 MIX'!C29 -> Aperol | D5: =+'4x4 MIX'!D29 -> EUAA Comets | E5: =+'4x4 MIX'!E29 -> 3 | F5: =+'4x4 MIX'!F29 -> 46186 | G5: =+'4x4 MIX'!G29 -> 0.375 | H5: =VLOOKUP(C5,'4x4 MIX'!$B$4:$J$18,9,) -> FRONTEX | I5: =VLOOKUP(D5,'4x4 MIX'!$B$4:$J$18,9,) -> EUAA | J5: =VLOOKUP(C5,'4x4 MIX'!$B$4:$I$18,2,) -> Monika Ciesielska | K5: =VLOOKUP(C5,'4x4 MIX'!$B$4:$I$18,3,) -> Evgenia Kalogeropoulou | L5: =VLOOKUP(C5,'4x4 MIX'!$B$4:$I$18,4,) -> Filipe Paisana | M5: =VLOOKUP(C5,'4x4 MIX'!$B$4:$I$18,5,) -> Jakub Banka | N5: =VLOOKUP($C5,'4x4 MIX'!$B$4:$I$18,6,) -> Claudiu Chirias | O5: =VLOOKUP($C5,'4x4 MIX'!$B$4:$I$18,7,) -> Georgios Dimitropoulos | P5: =VLOOKUP($D5,'4x4 MIX'!$B$4:$I$18,2,) -> Tania | Q5: =VLOOKUP($D5,'4x4 MIX'!$B$4:$I$18,3,) -> Claudia | R5: =VLOOKUP($D5,'4x4 MIX'!$B$4:$I$18,4,) -> Vasileios | S5: =VLOOKUP($D5,'4x4 MIX'!$B$4:$I$18,5,) -> Daniela | T5: =VLOOKUP($D5,'4x4 MIX'!$B$4:$I$18,6,) -> Maria
A6: =+'4x4 MIX'!A30 -> 4x4Mix | B6: =+'4x4 MIX'!B30 -> B | C6: =+'4x4 MIX'!C30 -> Dandy Dandelions | D6: =+'4x4 MIX'!D30 -> House of Medici | E6: =+'4x4 MIX'!E30 -> 4 | F6: =+'4x4 MIX'!F30 -> 46186 | G6: =+'4x4 MIX'!G30 -> 0.375 | H6: =VLOOKUP(C6,'4x4 MIX'!$B$4:$J$18,9,) -> FRONTEX | I6: =VLOOKUP(D6,'4x4 MIX'!$B$4:$J$18,9,) -> EMA | J6: =VLOOKUP(C6,'4x4 MIX'!$B$4:$I$18,2,) -> Anna Sofia Messeri | K6: =VLOOKUP(C6,'4x4 MIX'!$B$4:$I$18,3,) -> Natalia Alberska | L6: =VLOOKUP(C6,'4x4 MIX'!$B$4:$I$18,4,) -> Radovan Kyselica | M6: =VLOOKUP(C6,'4x4 MIX'!$B$4:$I$18,5,) -> Oliver Bosnar | N6: =VLOOKUP($C6,'4x4 MIX'!$B$4:$I$18,6,) -> Mateusz Rudzik | P6: =VLOOKUP($D6,'4x4 MIX'!$B$4:$I$18,2,) -> Mihaela Pereteatcu | Q6: =VLOOKUP($D6,'4x4 MIX'!$B$4:$I$18,3,) -> Valentina Cordo | R6: =VLOOKUP($D6,'4x4 MIX'!$B$4:$I$18,4,) -> Thibaut Sauces | S6: =VLOOKUP($D6,'4x4 MIX'!$B$4:$I$18,5,) -> Frank Pétavy | T6: =VLOOKUP($D6,'4x4 MIX'!$B$4:$I$18,6,) -> Evangelos Kotzagiorgis | U6: =VLOOKUP($D6,'4x4 MIX'!$B$4:$I$18,7,) -> Caroline Pothet
A7: =+'4x4 MIX'!A31 -> 4x4Mix | B7: =+'4x4 MIX'!B31 -> A | C7: =+'4x4 MIX'!C31 -> EUIPO 5 | D7: =+'4x4 MIX'!D31 -> EFSA 6 | E7: =+'4x4 MIX'!E31 -> 1 | F7: =+'4x4 MIX'!F31 -> 46186 | G7: =+'4x4 MIX'!G31 -> 0.375 | H7: =VLOOKUP(C7,'4x4 MIX'!$B$4:$J$18,9,) -> EUIPO | I7: =VLOOKUP(D7,'4x4 MIX'!$B$4:$J$18,9,) -> EFSA | J7: =VLOOKUP(C7,'4x4 MIX'!$B$4:$I$18,2,) -> CSENKE JUDIT | K7: =VLOOKUP(C7,'4x4 MIX'!$B$4:$I$18,3,) -> BILLERAULT AURELIEN | L7: =VLOOKUP(C7,'4x4 MIX'!$B$4:$I$18,4,) -> CORRADO ALESSANDRO | M7: =VLOOKUP(C7,'4x4 MIX'!$B$4:$I$18,5,) -> GURRIERI ROSARIO | N7: =VLOOKUP($C7,'4x4 MIX'!$B$4:$I$18,6,) -> ROMERO JULIAN | O7: =VLOOKUP($C7,'4x4 MIX'!$B$4:$I$18,7,) -> Federica Foti | P7: =VLOOKUP($D7,'4x4 MIX'!$B$4:$I$18,2,) -> Kralova Irena | Q7: =VLOOKUP($D7,'4x4 MIX'!$B$4:$I$18,3,) -> Pecoraro Simona | R7: =VLOOKUP($D7,'4x4 MIX'!$B$4:$I$18,4,) -> Marchese Emanuela | S7: =VLOOKUP($D7,'4x4 MIX'!$B$4:$I$18,5,) -> Marchesini Matteo | T7: =VLOOKUP($D7,'4x4 MIX'!$B$4:$I$18,6,) -> Ackerl Reinhard | U7: =VLOOKUP($D7,'4x4 MIX'!$B$4:$I$18,7,) -> Ferri Alessandro
A8: =+'4x4 MIX'!A32 -> 4x4Mix | B8: =+'4x4 MIX'!B32 -> D | C8: =+'4x4 MIX'!C32 -> Ferwanek | D8: =+'4x4 MIX'!D32 -> Mela Blinders | E8: =+'4x4 MIX'!E32 -> 2 | F8: =+'4x4 MIX'!F32 -> 46186 | G8: =+'4x4 MIX'!G32 -> 0.375 | H8: =VLOOKUP(C8,'4x4 MIX'!$B$4:$J$18,9,) -> FRONTEX | I8: =VLOOKUP(D8,'4x4 MIX'!$B$4:$J$18,9,) -> EUAA | J8: =VLOOKUP(C8,'4x4 MIX'!$B$4:$I$18,2,) -> Aleksandra Wajda | K8: =VLOOKUP(C8,'4x4 MIX'!$B$4:$I$18,3,) -> Federica Ferrari | L8: =VLOOKUP(C8,'4x4 MIX'!$B$4:$I$18,4,) -> Damian Krzak | M8: =VLOOKUP(C8,'4x4 MIX'!$B$4:$I$18,5,) -> Dariusz Neuhoff von der Ley | N8: =VLOOKUP($C8,'4x4 MIX'!$B$4:$I$18,6,) -> Jori Tyni | P8: =VLOOKUP($D8,'4x4 MIX'!$B$4:$I$18,2,) -> Filothei | Q8: =VLOOKUP($D8,'4x4 MIX'!$B$4:$I$18,3,) -> Anna Isabel | R8: =VLOOKUP($D8,'4x4 MIX'!$B$4:$I$18,4,) -> Raquel | S8: =VLOOKUP($D8,'4x4 MIX'!$B$4:$I$18,5,) -> Wade | T8: =VLOOKUP($D8,'4x4 MIX'!$B$4:$I$18,6,) -> Valeria
A9: =+'4x4 MIX'!A33 -> 4x4Mix | B9: =+'4x4 MIX'!B33 -> E | C9: =+'4x4 MIX'!C33 -> Sometimes maybe good | D9: =+'4x4 MIX'!D33 -> EUROPOL 4 MIX | E9: =+'4x4 MIX'!E33 -> 3 | F9: =+'4x4 MIX'!F33 -> 46186 | G9: =+'4x4 MIX'!G33 -> 0.39097222 | H9: =VLOOKUP(C9,'4x4 MIX'!$B$4:$J$18,9,) -> EUROJUST | I9: =VLOOKUP(D9,'4x4 MIX'!$B$4:$J$18,9,) -> EUROPOL | J9: =VLOOKUP(C9,'4x4 MIX'!$B$4:$I$18,2,) -> Seixas Joao | K9: =VLOOKUP(C9,'4x4 MIX'!$B$4:$I$18,3,) -> Conti Lucia | L9: =VLOOKUP(C9,'4x4 MIX'!$B$4:$I$18,4,) -> Klayn Aglika | M9: =VLOOKUP(C9,'4x4 MIX'!$B$4:$I$18,5,) -> Bonato Stefano | N9: =VLOOKUP($C9,'4x4 MIX'!$B$4:$I$18,6,) -> Rausch Laura | P9: =VLOOKUP($D9,'4x4 MIX'!$B$4:$I$18,2,) -> Stanciu Anca | Q9: =VLOOKUP($D9,'4x4 MIX'!$B$4:$I$18,3,) -> Serra Jose Manuel de Jesus | R9: =VLOOKUP($D9,'4x4 MIX'!$B$4:$I$18,4,) -> Ciprian Istudor | S9: =VLOOKUP($D9,'4x4 MIX'!$B$4:$I$18,5,) -> Federica C.
A10: =+'4x4 MIX'!A34 -> 4x4Mix | B10: =+'4x4 MIX'!B34 -> C | C10: =+'4x4 MIX'!C34 -> EUAA Comets | D10: =+'4x4 MIX'!D34 -> Che fastidio | E10: =+'4x4 MIX'!E34 -> 4 | F10: =+'4x4 MIX'!F34 -> 46186 | G10: =+'4x4 MIX'!G34 -> 0.39097222 | H10: =VLOOKUP(C10,'4x4 MIX'!$B$4:$J$18,9,) -> EUAA | I10: =VLOOKUP(D10,'4x4 MIX'!$B$4:$J$18,9,) -> JRC | J10: =VLOOKUP(C10,'4x4 MIX'!$B$4:$I$18,2,) -> Tania | K10: =VLOOKUP(C10,'4x4 MIX'!$B$4:$I$18,3,) -> Claudia | L10: =VLOOKUP(C10,'4x4 MIX'!$B$4:$I$18,4,) -> Vasileios | M10: =VLOOKUP(C10,'4x4 MIX'!$B$4:$I$18,5,) -> Daniela | N10: =VLOOKUP($C10,'4x4 MIX'!$B$4:$I$18,6,) -> Maria | P10: =VLOOKUP($D10,'4x4 MIX'!$B$4:$I$18,2,) -> Michela | Q10: =VLOOKUP($D10,'4x4 MIX'!$B$4:$I$18,3,) -> Silvio | R10: =VLOOKUP($D10,'4x4 MIX'!$B$4:$I$18,4,) -> Flavio | S10: =VLOOKUP($D10,'4x4 MIX'!$B$4:$I$18,5,) -> Elisa B.
A11: =+'4x4 MIX'!A35 -> 4x4Mix | B11: =+'4x4 MIX'!B35 -> B | C11: =+'4x4 MIX'!C35 -> House of Medici | D11: =+'4x4 MIX'!D35 -> REALL | E11: =+'4x4 MIX'!E35 -> 1 | F11: =+'4x4 MIX'!F35 -> 46186 | G11: =+'4x4 MIX'!G35 -> 0.39097222 | H11: =VLOOKUP(C11,'4x4 MIX'!$B$4:$J$18,9,) -> EMA | I11: =VLOOKUP(D11,'4x4 MIX'!$B$4:$J$18,9,) -> REA | J11: =VLOOKUP(C11,'4x4 MIX'!$B$4:$I$18,2,) -> Mihaela Pereteatcu | K11: =VLOOKUP(C11,'4x4 MIX'!$B$4:$I$18,3,) -> Valentina Cordo | L11: =VLOOKUP(C11,'4x4 MIX'!$B$4:$I$18,4,) -> Thibaut Sauces | M11: =VLOOKUP(C11,'4x4 MIX'!$B$4:$I$18,5,) -> Frank Pétavy | N11: =VLOOKUP($C11,'4x4 MIX'!$B$4:$I$18,6,) -> Evangelos Kotzagiorgis | O11: =VLOOKUP($C11,'4x4 MIX'!$B$4:$I$18,7,) -> Caroline Pothet | P11: =VLOOKUP($D11,'4x4 MIX'!$B$4:$I$18,2,) -> Scioni Barbara | Q11: =VLOOKUP($D11,'4x4 MIX'!$B$4:$I$18,3,) -> Medarova Keti | R11: =VLOOKUP($D11,'4x4 MIX'!$B$4:$I$18,4,) -> Paunovic Ogren | S11: =VLOOKUP($D11,'4x4 MIX'!$B$4:$I$18,5,) -> Amedja Ecki
A12: =+'4x4 MIX'!A36 -> 4x4Mix | B12: =+'4x4 MIX'!B36 -> A | C12: =+'4x4 MIX'!C36 -> EFSA 6 | D12: =+'4x4 MIX'!D36 -> Horizon setters | E12: =+'4x4 MIX'!E36 -> 2 | F12: =+'4x4 MIX'!F36 -> 46186 | G12: =+'4x4 MIX'!G36 -> 0.39097222 | H12: =VLOOKUP(C12,'4x4 MIX'!$B$4:$J$18,9,) -> EFSA | I12: =VLOOKUP(D12,'4x4 MIX'!$B$4:$J$18,9,) -> REA | J12: =VLOOKUP(C12,'4x4 MIX'!$B$4:$I$18,2,) -> Kralova Irena | K12: =VLOOKUP(C12,'4x4 MIX'!$B$4:$I$18,3,) -> Pecoraro Simona | L12: =VLOOKUP(C12,'4x4 MIX'!$B$4:$I$18,4,) -> Marchese Emanuela | M12: =VLOOKUP(C12,'4x4 MIX'!$B$4:$I$18,5,) -> Marchesini Matteo | N12: =VLOOKUP($C12,'4x4 MIX'!$B$4:$I$18,6,) -> Ackerl Reinhard | O12: =VLOOKUP($C12,'4x4 MIX'!$B$4:$I$18,7,) -> Ferri Alessandro | P12: =VLOOKUP($D12,'4x4 MIX'!$B$4:$I$18,2,) -> Piiroja Ivi | Q12: =VLOOKUP($D12,'4x4 MIX'!$B$4:$I$18,3,) -> ANTONELLI Margherita | R12: =VLOOKUP($D12,'4x4 MIX'!$B$4:$I$18,4,) -> Deniz Javier | S12: =VLOOKUP($D12,'4x4 MIX'!$B$4:$I$18,5,) -> Napolitano Andrea
A13: =+'4x4 MIX'!A37 -> 4x4Mix | B13: =+'4x4 MIX'!B37 -> D | C13: =+'4x4 MIX'!C37 -> Mela Blinders | D13: =+'4x4 MIX'!D37 -> Sand by me | E13: =+'4x4 MIX'!E37 -> 3 | F13: =+'4x4 MIX'!F37 -> 46186 | G13: =+'4x4 MIX'!G37 -> 0.40694444 | H13: =VLOOKUP(C13,'4x4 MIX'!$B$4:$J$18,9,) -> EUAA | I13: =VLOOKUP(D13,'4x4 MIX'!$B$4:$J$18,9,) -> JRC | J13: =VLOOKUP(C13,'4x4 MIX'!$B$4:$I$18,2,) -> Filothei | K13: =VLOOKUP(C13,'4x4 MIX'!$B$4:$I$18,3,) -> Anna Isabel | L13: =VLOOKUP(C13,'4x4 MIX'!$B$4:$I$18,4,) -> Raquel | M13: =VLOOKUP(C13,'4x4 MIX'!$B$4:$I$18,5,) -> Wade | N13: =VLOOKUP($C13,'4x4 MIX'!$B$4:$I$18,6,) -> Valeria | P13: =VLOOKUP($D13,'4x4 MIX'!$B$4:$I$18,2,) -> Daniele | Q13: =VLOOKUP($D13,'4x4 MIX'!$B$4:$I$18,3,) -> Fabio | R13: =VLOOKUP($D13,'4x4 MIX'!$B$4:$I$18,4,) -> Roberto | S13: =VLOOKUP($D13,'4x4 MIX'!$B$4:$I$18,5,) -> Federica R. | T13: =VLOOKUP($D13,'4x4 MIX'!$B$4:$I$18,6,) -> Ilaria
A14: =+'4x4 MIX'!A38 -> 4x4Mix | B14: =+'4x4 MIX'!B38 -> E | C14: =+'4x4 MIX'!C38 -> EUROPOL 4 MIX | D14: =+'4x4 MIX'!D38 -> Upsand Down | E14: =+'4x4 MIX'!E38 -> 4 | F14: =+'4x4 MIX'!F38 -> 46186 | G14: =+'4x4 MIX'!G38 -> 0.40694444 | H14: =VLOOKUP(C14,'4x4 MIX'!$B$4:$J$18,9,) -> EUROPOL | I14: =VLOOKUP(D14,'4x4 MIX'!$B$4:$J$18,9,) -> JRC | J14: =VLOOKUP(C14,'4x4 MIX'!$B$4:$I$18,2,) -> Stanciu Anca | K14: =VLOOKUP(C14,'4x4 MIX'!$B$4:$I$18,3,) -> Serra Jose Manuel de Jesus | L14: =VLOOKUP(C14,'4x4 MIX'!$B$4:$I$18,4,) -> Ciprian Istudor | M14: =VLOOKUP(C14,'4x4 MIX'!$B$4:$I$18,5,) -> Federica C. | P14: =VLOOKUP($D14,'4x4 MIX'!$B$4:$I$18,2,) -> Tom | Q14: =VLOOKUP($D14,'4x4 MIX'!$B$4:$I$18,3,) -> Mauro Gabbarini | R14: =VLOOKUP($D14,'4x4 MIX'!$B$4:$I$18,4,) -> Federica Ferretti | S14: =VLOOKUP($D14,'4x4 MIX'!$B$4:$I$18,5,) -> Diana
A15: =+'4x4 MIX'!A39 -> 4x4Mix | B15: =+'4x4 MIX'!B39 -> C | C15: =+'4x4 MIX'!C39 -> Aperol | D15: =+'4x4 MIX'!D39 -> Che fastidio | E15: =+'4x4 MIX'!E39 -> 1 | F15: =+'4x4 MIX'!F39 -> 46186 | G15: =+'4x4 MIX'!G39 -> 0.40694444 | H15: =VLOOKUP(C15,'4x4 MIX'!$B$4:$J$18,9,) -> FRONTEX | I15: =VLOOKUP(D15,'4x4 MIX'!$B$4:$J$18,9,) -> JRC | J15: =VLOOKUP(C15,'4x4 MIX'!$B$4:$I$18,2,) -> Monika Ciesielska | K15: =VLOOKUP(C15,'4x4 MIX'!$B$4:$I$18,3,) -> Evgenia Kalogeropoulou | L15: =VLOOKUP(C15,'4x4 MIX'!$B$4:$I$18,4,) -> Filipe Paisana | M15: =VLOOKUP(C15,'4x4 MIX'!$B$4:$I$18,5,) -> Jakub Banka | N15: =VLOOKUP($C15,'4x4 MIX'!$B$4:$I$18,6,) -> Claudiu Chirias | O15: =VLOOKUP($C15,'4x4 MIX'!$B$4:$I$18,7,) -> Georgios Dimitropoulos | P15: =VLOOKUP($D15,'4x4 MIX'!$B$4:$I$18,2,) -> Michela | Q15: =VLOOKUP($D15,'4x4 MIX'!$B$4:$I$18,3,) -> Silvio | R15: =VLOOKUP($D15,'4x4 MIX'!$B$4:$I$18,4,) -> Flavio | S15: =VLOOKUP($D15,'4x4 MIX'!$B$4:$I$18,5,) -> Elisa B.
A16: =+'4x4 MIX'!A40 -> 4x4Mix | B16: =+'4x4 MIX'!B40 -> B | C16: =+'4x4 MIX'!C40 -> Dandy Dandelions | D16: =+'4x4 MIX'!D40 -> REALL | E16: =+'4x4 MIX'!E40 -> 2 | F16: =+'4x4 MIX'!F40 -> 46186 | G16: =+'4x4 MIX'!G40 -> 0.40694444 | H16: =VLOOKUP(C16,'4x4 MIX'!$B$4:$J$18,9,) -> FRONTEX | I16: =VLOOKUP(D16,'4x4 MIX'!$B$4:$J$18,9,) -> REA | J16: =VLOOKUP(C16,'4x4 MIX'!$B$4:$I$18,2,) -> Anna Sofia Messeri | K16: =VLOOKUP(C16,'4x4 MIX'!$B$4:$I$18,3,) -> Natalia Alberska | L16: =VLOOKUP(C16,'4x4 MIX'!$B$4:$I$18,4,) -> Radovan Kyselica | M16: =VLOOKUP(C16,'4x4 MIX'!$B$4:$I$18,5,) -> Oliver Bosnar | N16: =VLOOKUP($C16,'4x4 MIX'!$B$4:$I$18,6,) -> Mateusz Rudzik | P16: =VLOOKUP($D16,'4x4 MIX'!$B$4:$I$18,2,) -> Scioni Barbara | Q16: =VLOOKUP($D16,'4x4 MIX'!$B$4:$I$18,3,) -> Medarova Keti | R16: =VLOOKUP($D16,'4x4 MIX'!$B$4:$I$18,4,) -> Paunovic Ogren | S16: =VLOOKUP($D16,'4x4 MIX'!$B$4:$I$18,5,) -> Amedja Ecki
A17: =+'4x4 MIX'!A41 -> 4x4Mix | B17: =+'4x4 MIX'!B41 -> A | C17: =+'4x4 MIX'!C41 -> EUIPO 5 | D17: =+'4x4 MIX'!D41 -> Horizon setters | E17: =+'4x4 MIX'!E41 -> 3 | F17: =+'4x4 MIX'!F41 -> 46186 | G17: =+'4x4 MIX'!G41 -> 0.42291667 | H17: =VLOOKUP(C17,'4x4 MIX'!$B$4:$J$18,9,) -> EUIPO | I17: =VLOOKUP(D17,'4x4 MIX'!$B$4:$J$18,9,) -> REA | J17: =VLOOKUP(C17,'4x4 MIX'!$B$4:$I$18,2,) -> CSENKE JUDIT | K17: =VLOOKUP(C17,'4x4 MIX'!$B$4:$I$18,3,) -> BILLERAULT AURELIEN | L17: =VLOOKUP(C17,'4x4 MIX'!$B$4:$I$18,4,) -> CORRADO ALESSANDRO | M17: =VLOOKUP(C17,'4x4 MIX'!$B$4:$I$18,5,) -> GURRIERI ROSARIO | N17: =VLOOKUP($C17,'4x4 MIX'!$B$4:$I$18,6,) -> ROMERO JULIAN | O17: =VLOOKUP($C17,'4x4 MIX'!$B$4:$I$18,7,) -> Federica Foti | P17: =VLOOKUP($D17,'4x4 MIX'!$B$4:$I$18,2,) -> Piiroja Ivi | Q17: =VLOOKUP($D17,'4x4 MIX'!$B$4:$I$18,3,) -> ANTONELLI Margherita | R17: =VLOOKUP($D17,'4x4 MIX'!$B$4:$I$18,4,) -> Deniz Javier | S17: =VLOOKUP($D17,'4x4 MIX'!$B$4:$I$18,5,) -> Napolitano Andrea
A18: =+'4x4 MIX'!A42 -> 4x4Mix | B18: =+'4x4 MIX'!B42 -> D | C18: =+'4x4 MIX'!C42 -> Ferwanek | D18: =+'4x4 MIX'!D42 -> Sand by me | E18: =+'4x4 MIX'!E42 -> 4 | F18: =+'4x4 MIX'!F42 -> 46186 | G18: =+'4x4 MIX'!G42 -> 0.42291667 | H18: =VLOOKUP(C18,'4x4 MIX'!$B$4:$J$18,9,) -> FRONTEX | I18: =VLOOKUP(D18,'4x4 MIX'!$B$4:$J$18,9,) -> JRC | J18: =VLOOKUP(C18,'4x4 MIX'!$B$4:$I$18,2,) -> Aleksandra Wajda | K18: =VLOOKUP(C18,'4x4 MIX'!$B$4:$I$18,3,) -> Federica Ferrari | L18: =VLOOKUP(C18,'4x4 MIX'!$B$4:$I$18,4,) -> Damian Krzak | M18: =VLOOKUP(C18,'4x4 MIX'!$B$4:$I$18,5,) -> Dariusz Neuhoff von der Ley | N18: =VLOOKUP($C18,'4x4 MIX'!$B$4:$I$18,6,) -> Jori Tyni | P18: =VLOOKUP($D18,'4x4 MIX'!$B$4:$I$18,2,) -> Daniele | Q18: =VLOOKUP($D18,'4x4 MIX'!$B$4:$I$18,3,) -> Fabio | R18: =VLOOKUP($D18,'4x4 MIX'!$B$4:$I$18,4,) -> Roberto | S18: =VLOOKUP($D18,'4x4 MIX'!$B$4:$I$18,5,) -> Federica R. | T18: =VLOOKUP($D18,'4x4 MIX'!$B$4:$I$18,6,) -> Ilaria
A19: =+'4x4 MIX'!A43 -> 4x4Mix | B19: =+'4x4 MIX'!B43 -> E | C19: =+'4x4 MIX'!C43 -> Sometimes maybe good | D19: =+'4x4 MIX'!D43 -> Upsand Down | E19: =+'4x4 MIX'!E43 -> 1 | F19: =+'4x4 MIX'!F43 -> 46186 | G19: =+'4x4 MIX'!G43 -> 0.42291667 | H19: =VLOOKUP(C19,'4x4 MIX'!$B$4:$J$18,9,) -> EUROJUST | I19: =VLOOKUP(D19,'4x4 MIX'!$B$4:$J$18,9,) -> JRC | J19: =VLOOKUP(C19,'4x4 MIX'!$B$4:$I$18,2,) -> Seixas Joao | K19: =VLOOKUP(C19,'4x4 MIX'!$B$4:$I$18,3,) -> Conti Lucia | L19: =VLOOKUP(C19,'4x4 MIX'!$B$4:$I$18,4,) -> Klayn Aglika | M19: =VLOOKUP(C19,'4x4 MIX'!$B$4:$I$18,5,) -> Bonato Stefano | N19: =VLOOKUP($C19,'4x4 MIX'!$B$4:$I$18,6,) -> Rausch Laura | P19: =VLOOKUP($D19,'4x4 MIX'!$B$4:$I$18,2,) -> Tom | Q19: =VLOOKUP($D19,'4x4 MIX'!$B$4:$I$18,3,) -> Mauro Gabbarini | R19: =VLOOKUP($D19,'4x4 MIX'!$B$4:$I$18,4,) -> Federica Ferretti | S19: =VLOOKUP($D19,'4x4 MIX'!$B$4:$I$18,5,) -> Diana
A20: =+'4x4 MIX'!A44 -> 4x4Mix | B20: =+'4x4 MIX'!B44 -> Playoffs | C20: =+'4x4 MIX'!C44 -> Group winner 5th best ranked team | D20: =+'4x4 MIX'!D44 -> Group winner 4th best ranked team | E20: =+'4x4 MIX'!E44 -> 1 | F20: =+'4x4 MIX'!F44 -> 46186 | G20: =+'4x4 MIX'!G44 -> 0.43888889
A21: =+'4x4 MIX'!A45 -> 4x4Mix | B21: =+'4x4 MIX'!B45 -> Playoffs | C21: =+'4x4 MIX'!C45 -> Group winner 3rd best ranked team | D21: =+'4x4 MIX'!D45 -> Best second of the groups | E21: =+'4x4 MIX'!E45 -> 2 | F21: =+'4x4 MIX'!F45 -> 46186 | G21: =+'4x4 MIX'!G45 -> 0.43888889
A22: =+'2x2M'!A31 -> 2x2M | B22: =+'2x2M'!B31 -> A | C22: =+'2x2M'!C31 -> Too hot for indoor | D22: =+'2x2M'!D31 -> Chill-out | E22: =+'2x2M'!E31 -> 1 | F22: =+'2x2M'!F31 -> 46186 | G22: =+'2x2M'!G31 -> 0.45486111 | H22: =VLOOKUP(C22,'2x2M'!$B$5:$E$18,4,) -> JRC | I22: =VLOOKUP(D22,'2x2M'!$B$5:$E$18,4,) -> FRONTEX | J22: =VLOOKUP(C22,'2x2M'!B$5:D$18,2,) -> Daniele | K22: =VLOOKUP(C22,'2x2M'!$B$5:$D$18,3,) -> Carlo | L22: =VLOOKUP(D22,'2x2M'!$B$5:$D$18,2,) -> Mateusz Rudzik | M22: =VLOOKUP(D22,'2x2M'!$B$5:$D$18,3,) -> Mariusz Dzierżawski
A23: =+'2x2M'!A32 -> 2x2M | B23: =+'2x2M'!B32 -> B | C23: =+'2x2M'!C32 -> Europol 2x2 men | D23: =+'2x2M'!D32 -> Ballbreakers | E23: =+'2x2M'!E32 -> 2 | F23: =+'2x2M'!F32 -> 46186 | G23: =+'2x2M'!G32 -> 0.45486111 | H23: =VLOOKUP(C23,'2x2M'!$B$5:$E$18,4,) -> EUROPOL | I23: =VLOOKUP(D23,'2x2M'!$B$5:$E$18,4,) -> FRONTEX | J23: =VLOOKUP(C23,'2x2M'!B$5:D$18,2,) -> Ciprian Istudor | K23: =VLOOKUP(C23,'2x2M'!$B$5:$D$18,3,) -> Ionut Sava | L23: =VLOOKUP(D23,'2x2M'!$B$5:$D$18,2,) -> Oliver Bosnar | M23: =VLOOKUP(D23,'2x2M'!$B$5:$D$18,3,) -> Michal Narojek
A24: =+'2x2M'!A33 -> 2x2M | B24: =+'2x2M'!B33 -> C | C24: =+'2x2M'!C33 -> Bacalhau&porchetta | D24: =+'2x2M'!D33 -> DP's | E24: =+'2x2M'!E33 -> 1 | F24: =+'2x2M'!F33 -> 46186 | G24: =+'2x2M'!G33 -> 0.47083333 | H24: =VLOOKUP(C24,'2x2M'!$B$5:$E$18,4,) -> EUROJUST | I24: =VLOOKUP(D24,'2x2M'!$B$5:$E$18,4,) -> FRONTEX | J24: =VLOOKUP(C24,'2x2M'!B$5:D$18,2,) -> Seixas Joao | K24: =VLOOKUP(C24,'2x2M'!$B$5:$D$18,3,) -> Bonato Stefano | L24: =VLOOKUP(D24,'2x2M'!$B$5:$D$18,2,) -> Filipe Paisana | M24: =VLOOKUP(D24,'2x2M'!$B$5:$D$18,3,) -> Georgios Dimitropoulos
A25: =+'2x2M'!A34 -> 2x2M | B25: =+'2x2M'!B34 -> D | C25: =+'2x2M'!C34 -> EFSA 1 | D25: =+'2x2M'!D34 -> Que farà Farà | E25: =+'2x2M'!E34 -> 2 | F25: =+'2x2M'!F34 -> 46186 | G25: =+'2x2M'!G34 -> 0.47083333 | H25: =VLOOKUP(C25,'2x2M'!$B$5:$E$18,4,) -> EFSA | I25: =VLOOKUP(D25,'2x2M'!$B$5:$E$18,4,) -> JRC | J25: =VLOOKUP(C25,'2x2M'!B$5:D$18,2,) -> Marchesini Matteo | K25: =VLOOKUP(C25,'2x2M'!$B$5:$D$18,3,) -> Ackerl Reinhard | L25: =VLOOKUP(D25,'2x2M'!$B$5:$D$18,2,) -> Fabio | M25: =VLOOKUP(D25,'2x2M'!$B$5:$D$18,3,) -> Roberto
A26: =+'2x2M'!A35 -> 2x2M | B26: =+'2x2M'!B35 -> A | C26: =+'2x2M'!C35 -> Too hot for indoor | D26: =+'2x2M'!D35 -> EFSA 2 | E26: =+'2x2M'!E35 -> 1 | F26: =+'2x2M'!F35 -> 46186 | G26: =+'2x2M'!G35 -> 0.48680556 | H26: =VLOOKUP(C26,'2x2M'!$B$5:$E$18,4,) -> JRC | I26: =VLOOKUP(D26,'2x2M'!$B$5:$E$18,4,) -> EFSA | J26: =VLOOKUP(C26,'2x2M'!B$5:D$18,2,) -> Daniele | K26: =VLOOKUP(C26,'2x2M'!$B$5:$D$18,3,) -> Carlo | L26: =VLOOKUP(D26,'2x2M'!$B$5:$D$18,2,) -> Ferri Alessandro | M26: =VLOOKUP(D26,'2x2M'!$B$5:$D$18,3,) -> Marinelli Andrea
A27: =+'2x2M'!A36 -> 2x2M | B27: =+'2x2M'!B36 -> B | C27: =+'2x2M'!C36 -> JRC 3 | D27: =+'2x2M'!D36 -> Beach control | E27: =+'2x2M'!E36 -> 2 | F27: =+'2x2M'!F36 -> 46186 | G27: =+'2x2M'!G36 -> 0.48680556 | H27: =VLOOKUP(C27,'2x2M'!$B$5:$E$18,4,) -> JRC | I27: =VLOOKUP(D27,'2x2M'!$B$5:$E$18,4,) -> EMA | J27: =VLOOKUP(C27,'2x2M'!B$5:D$18,2,) -> Mauro Gabbarini | K27: =VLOOKUP(C27,'2x2M'!$B$5:$D$18,3,) -> Tom | L27: =VLOOKUP(D27,'2x2M'!$B$5:$D$18,2,) -> Evangelos Kotzagiorgis | M27: =VLOOKUP(D27,'2x2M'!$B$5:$D$18,3,) -> Alex Gentimis
A28: =+'2x2M'!A37 -> 2x2M | B28: =+'2x2M'!B37 -> C | C28: =+'2x2M'!C37 -> DP's | D28: =+'2x2M'!D37 -> I transalpini | E28: =+'2x2M'!E37 -> 1 | F28: =+'2x2M'!F37 -> 46186 | G28: =+'2x2M'!G37 -> 0.50277778 | H28: =VLOOKUP(C28,'2x2M'!$B$5:$E$18,4,) -> FRONTEX | I28: =VLOOKUP(D28,'2x2M'!$B$5:$E$18,4,) -> EMA | J28: =VLOOKUP(C28,'2x2M'!B$5:D$18,2,) -> Filipe Paisana | K28: =VLOOKUP(C28,'2x2M'!$B$5:$D$18,3,) -> Georgios Dimitropoulos | L28: =VLOOKUP(D28,'2x2M'!$B$5:$D$18,2,) -> Frank Pétavy | M28: =VLOOKUP(D28,'2x2M'!$B$5:$D$18,3,) -> Thibaut Sauces
A29: =+'2x2M'!A38 -> 2x2M | B29: =+'2x2M'!B38 -> D | C29: =+'2x2M'!C38 -> Que farà Farà | D29: =+'2x2M'!D38 -> Dunaj & Wisla | E29: =+'2x2M'!E38 -> 2 | F29: =+'2x2M'!F38 -> 46186 | G29: =+'2x2M'!G38 -> 0.50277778 | H29: =VLOOKUP(C29,'2x2M'!$B$5:$E$18,4,) -> JRC | I29: =VLOOKUP(D29,'2x2M'!$B$5:$E$18,4,) -> FRONTEX | J29: =VLOOKUP(C29,'2x2M'!B$5:D$18,2,) -> Fabio | K29: =VLOOKUP(C29,'2x2M'!$B$5:$D$18,3,) -> Roberto | L29: =VLOOKUP(D29,'2x2M'!$B$5:$D$18,2,) -> Radovan Kyselica | M29: =VLOOKUP(D29,'2x2M'!$B$5:$D$18,3,) -> Dariusz Neuhoff von der Ley
A30: =+'2x2M'!A39 -> 2x2M | B30: =+'2x2M'!B39 -> A | C30: =+'2x2M'!C39 -> EFSA 2 | D30: =+'2x2M'!D39 -> Valletta's Tritons | E30: =+'2x2M'!E39 -> 1 | F30: =+'2x2M'!F39 -> 46186 | G30: =+'2x2M'!G39 -> 0.51875 | H30: =VLOOKUP(C30,'2x2M'!$B$5:$E$18,4,) -> EFSA | I30: =VLOOKUP(D30,'2x2M'!$B$5:$E$18,4,) -> EUAA | J30: =VLOOKUP(C30,'2x2M'!B$5:D$18,2,) -> Ferri Alessandro | K30: =VLOOKUP(C30,'2x2M'!$B$5:$D$18,3,) -> Marinelli Andrea | L30: =VLOOKUP(D30,'2x2M'!$B$5:$D$18,2,) -> Vasileios | M30: =VLOOKUP(D30,'2x2M'!$B$5:$D$18,3,) -> Wade
A31: =+'2x2M'!A40 -> 2x2M | B31: =+'2x2M'!B40 -> B | C31: =+'2x2M'!C40 -> Europol 2x2 men | D31: =+'2x2M'!D40 -> JRC 3 | E31: =+'2x2M'!E40 -> 2 | F31: =+'2x2M'!F40 -> 46186 | G31: =+'2x2M'!G40 -> 0.51875 | H31: =VLOOKUP(C31,'2x2M'!$B$5:$E$18,4,) -> EUROPOL | I31: =VLOOKUP(D31,'2x2M'!$B$5:$E$18,4,) -> JRC | J31: =VLOOKUP(C31,'2x2M'!B$5:D$18,2,) -> Ciprian Istudor | K31: =VLOOKUP(C31,'2x2M'!$B$5:$D$18,3,) -> Ionut Sava | L31: =VLOOKUP(D31,'2x2M'!$B$5:$D$18,2,) -> Mauro Gabbarini | M31: =VLOOKUP(D31,'2x2M'!$B$5:$D$18,3,) -> Tom
A32: =+'2x2M'!A41 -> 2x2M | B32: =+'2x2M'!B41 -> C | C32: =+'2x2M'!C41 -> Bacalhau&porchetta | D32: =+'2x2M'!D41 -> I transalpini | E32: =+'2x2M'!E41 -> 1 | F32: =+'2x2M'!F41 -> 46186 | G32: =+'2x2M'!G41 -> 0.53472222 | H32: =VLOOKUP(C32,'2x2M'!$B$5:$E$18,4,) -> EUROJUST | I32: =VLOOKUP(D32,'2x2M'!$B$5:$E$18,4,) -> EMA | J32: =VLOOKUP(C32,'2x2M'!B$5:D$18,2,) -> Seixas Joao | K32: =VLOOKUP(C32,'2x2M'!$B$5:$D$18,3,) -> Bonato Stefano | L32: =VLOOKUP(D32,'2x2M'!$B$5:$D$18,2,) -> Frank Pétavy | M32: =VLOOKUP(D32,'2x2M'!$B$5:$D$18,3,) -> Thibaut Sauces
A33: =+'2x2M'!A42 -> 2x2M | B33: =+'2x2M'!B42 -> D | C33: =+'2x2M'!C42 -> EFSA 1 | D33: =+'2x2M'!D42 -> Dunaj & Wisla | E33: =+'2x2M'!E42 -> 2 | F33: =+'2x2M'!F42 -> 46186 | G33: =+'2x2M'!G42 -> 0.53472222 | H33: =VLOOKUP(C33,'2x2M'!$B$5:$E$18,4,) -> EFSA | I33: =VLOOKUP(D33,'2x2M'!$B$5:$E$18,4,) -> FRONTEX | J33: =VLOOKUP(C33,'2x2M'!B$5:D$18,2,) -> Marchesini Matteo | K33: =VLOOKUP(C33,'2x2M'!$B$5:$D$18,3,) -> Ackerl Reinhard | L33: =VLOOKUP(D33,'2x2M'!$B$5:$D$18,2,) -> Radovan Kyselica | M33: =VLOOKUP(D33,'2x2M'!$B$5:$D$18,3,) -> Dariusz Neuhoff von der Ley
... A39: =+'2x2M'!A48 -> 2x2M | B39: =+'2x2M'!B48 -> B | C39: =+'2x2M'!C48 -> Ballbreakers | D39: =+'2x2M'!D48 -> JRC 3 | E39: =+'2x2M'!E48 -> 2 | F39: =+'2x2M'!F48 -> 46186 | G39: =+'2x2M'!G48 -> 0.58263889 | H39: =VLOOKUP(C39,'2x2M'!$B$5:$E$18,4,) -> FRONTEX | I39: =VLOOKUP(D39,'2x2M'!$B$5:$E$18,4,) -> JRC | J39: =VLOOKUP(C39,'2x2M'!B$5:D$18,2,) -> Oliver Bosnar | K39: =VLOOKUP(C39,'2x2M'!$B$5:$D$18,3,) -> Michal Narojek | L39: =VLOOKUP(D39,'2x2M'!$B$5:$D$18,2,) -> Mauro Gabbarini | M39: =VLOOKUP(D39,'2x2M'!$B$5:$D$18,3,) -> Tom
A40: =+'2x2F'!A28 -> 2x2F | B40: =+'2x2F'!B28 -> C | C40: =+'2x2F'!C28 -> FedAle | D40: =+'2x2F'!D28 -> Blue Lagoon Spritz | E40: =+'2x2F'!E28 -> 3 | F40: =+'2x2F'!F28 -> 46186 | G40: =+'2x2F'!G28 -> 0.45486111 | H40: =VLOOKUP(C40,'2x2F'!$B$5:$E$15,4,) -> FRONTEX | I40: =VLOOKUP(D40,'2x2F'!$B$5:$E$15,4,) -> EUAA | J40: =VLOOKUP(C40,'2x2F'!$B$5:$D$15,2,) -> Aleksandra Wajda | K40: =VLOOKUP(C40,'2x2F'!$B$5:$D$15,3,) -> Federica Ferrari | L40: =VLOOKUP(D40,'2x2F'!$B$5:$D$15,2,) -> Claudia | M40: =VLOOKUP(D40,'2x2F'!$B$5:$D$15,3,) -> Tania
A41: =+'2x2F'!A29 -> 2x2F | B41: =+'2x2F'!B29 -> B | C41: =+'2x2F'!C29 -> MURO ! | D41: =+'2x2F'!D29 -> EFSA 7 | E41: =+'2x2F'!E29 -> 4 | F41: =+'2x2F'!F29 -> 46186 | G41: =+'2x2F'!G29 -> 0.45486111 | H41: =VLOOKUP(C41,'2x2F'!$B$5:$E$15,4,) -> FRONTEX | I41: =VLOOKUP(D41,'2x2F'!$B$5:$E$15,4,) -> EFSA | J41: =VLOOKUP(C41,'2x2F'!$B$5:$D$15,2,) -> Natalia Alberska | K41: =VLOOKUP(C41,'2x2F'!$B$5:$D$15,3,) -> Anna Jaroszuk | L41: =VLOOKUP(D41,'2x2F'!$B$5:$D$15,2,) -> Kralova Irena | M41: =VLOOKUP(D41,'2x2F'!$B$5:$D$15,3,) -> Pecoraro Simona
A42: =+'2x2F'!A30 -> 2x2F | B42: =+'2x2F'!B30 -> A | C42: =+'2x2F'!C30 -> ITAegean | D42: =+'2x2F'!D30 -> Nanook | E42: =+'2x2F'!E30 -> 3 | F42: =+'2x2F'!F30 -> 46186 | G42: =+'2x2F'!G30 -> 0.47083333 | H42: =VLOOKUP(C42,'2x2F'!$B$5:$E$15,4,) -> FRONTEX | I42: =VLOOKUP(D42,'2x2F'!$B$5:$E$15,4,) -> EUROJUST | J42: =VLOOKUP(C42,'2x2F'!$B$5:$D$15,2,) -> Evgenia Kalogeropoulou | K42: =VLOOKUP(C42,'2x2F'!$B$5:$D$15,3,) -> Anna Sofia Messeri | L42: =VLOOKUP(D42,'2x2F'!$B$5:$D$15,2,) -> Conti Lucia | M42: =VLOOKUP(D42,'2x2F'!$B$5:$D$15,3,) -> Klayn Aglika
A43: =+'2x2F'!A31 -> 2x2F | B43: =+'2x2F'!B31 -> A | C43: =+'2x2F'!C31 -> Pastizzi Patrol | D43: =+'2x2F'!D31 -> Disaqueens | E43: =+'2x2F'!E31 -> 4 | F43: =+'2x2F'!F31 -> 46186 | G43: =+'2x2F'!G31 -> 0.47083333 | H43: =VLOOKUP(C43,'2x2F'!$B$5:$E$15,4,) -> EUAA | I43: =VLOOKUP(D43,'2x2F'!$B$5:$E$15,4,) -> JRC | J43: =VLOOKUP(C43,'2x2F'!$B$5:$D$15,2,) -> Daniela | K43: =VLOOKUP(C43,'2x2F'!$B$5:$D$15,3,) -> Raquel | L43: =VLOOKUP(D43,'2x2F'!$B$5:$D$15,2,) -> Boba | M43: =VLOOKUP(D43,'2x2F'!$B$5:$D$15,3,) -> Federica R.
A44: =+'2x2F'!A32 -> 2x2F | B44: =+'2x2F'!B32 -> B | C44: =+'2x2F'!C32 -> Barrakka Gardeners | D44: =+'2x2F'!D32 -> JRC 12 | E44: =+'2x2F'!E32 -> 3 | F44: =+'2x2F'!F32 -> 46186 | G44: =+'2x2F'!G32 -> 0.48680556 | H44: =VLOOKUP(C44,'2x2F'!$B$5:$E$15,4,) -> EUAA | I44: =VLOOKUP(D44,'2x2F'!$B$5:$E$15,4,) -> JRC | J44: =VLOOKUP(C44,'2x2F'!$B$5:$D$15,2,) -> Filothei | K44: =VLOOKUP(C44,'2x2F'!$B$5:$D$15,3,) -> Maria | L44: =VLOOKUP(D44,'2x2F'!$B$5:$D$15,2,) -> Elisa B. | M44: =VLOOKUP(D44,'2x2F'!$B$5:$D$15,3,) -> Ilaria
A45: =+'2x2F'!A33 -> 2x2F | B45: =+'2x2F'!B33 -> C | C45: =+'2x2F'!C33 -> FedAle | D45: =+'2x2F'!D33 -> EUROPOL F | E45: =+'2x2F'!E33 -> 4 | F45: =+'2x2F'!F33 -> 46186 | G45: =+'2x2F'!G33 -> 0.48680556 | H45: =VLOOKUP(C45,'2x2F'!$B$5:$E$15,4,) -> FRONTEX | I45: =VLOOKUP(D45,'2x2F'!$B$5:$E$15,4,) -> EUROPOL | J45: =VLOOKUP(C45,'2x2F'!$B$5:$D$15,2,) -> Aleksandra Wajda | K45: =VLOOKUP(C45,'2x2F'!$B$5:$D$15,3,) -> Federica Ferrari | L45: =VLOOKUP(D45,'2x2F'!$B$5:$D$15,2,) -> Stanciu Anca | M45: =VLOOKUP(D45,'2x2F'!$B$5:$D$15,3,) -> Rausch Laura
A46: =+'2x2F'!A34 -> 2x2F | B46: =+'2x2F'!B34 -> A | C46: =+'2x2F'!C34 -> ITAegean | D46: =+'2x2F'!D34 -> Pastizzi Patrol | E46: =+'2x2F'!E34 -> 3 | F46: =+'2x2F'!F34 -> 46186 | G46: =+'2x2F'!G34 -> 0.50277778 | H46: =VLOOKUP(C46,'2x2F'!$B$5:$E$15,4,) -> FRONTEX | I46: =VLOOKUP(D46,'2x2F'!$B$5:$E$15,4,) -> EUAA | J46: =VLOOKUP(C46,'2x2F'!$B$5:$D$15,2,) -> Evgenia Kalogeropoulou | K46: =VLOOKUP(C46,'2x2F'!$B$5:$D$15,3,) -> Anna Sofia Messeri | L46: =VLOOKUP(D46,'2x2F'!$B$5:$D$15,2,) -> Daniela | M46: =VLOOKUP(D46,'2x2F'!$B$5:$D$15,3,) -> Raquel
A47: =+'2x2F'!A35 -> 2x2F | B47: =+'2x2F'!B35 -> B | C47: =+'2x2F'!C35 -> MURO ! | D47: =+'2x2F'!D35 -> Barrakka Gardeners | E47: =+'2x2F'!E35 -> 4 | F47: =+'2x2F'!F35 -> 46186 | G47: =+'2x2F'!G35 -> 0.50277778 | H47: =VLOOKUP(C47,'2x2F'!$B$5:$E$15,4,) -> FRONTEX | I47: =VLOOKUP(D47,'2x2F'!$B$5:$E$15,4,) -> EUAA | J47: =VLOOKUP(C47,'2x2F'!$B$5:$D$15,2,) -> Natalia Alberska | K47: =VLOOKUP(C47,'2x2F'!$B$5:$D$15,3,) -> Anna Jaroszuk | L47: =VLOOKUP(D47,'2x2F'!$B$5:$D$15,2,) -> Filothei | M47: =VLOOKUP(D47,'2x2F'!$B$5:$D$15,3,) -> Maria
...

Sheet Agency calendar
A2: Agency | C2: REA
C4: Tournament | D4: Group | E4: Team 1 | F4: Team 2 | G4: Court | H4: Date | I4: Time | P4: {=_xlfn._xlws.SORT(_xlfn.UNIQUE(_xlfn.TOCOL(Global!H5:I96,1,1)))} -> ECDC
C5: {=_xlfn._xlws.FILTER(Global!A5:G96,(Global!H5:H96=C2)+(Global!I5:I96=C2))} -> 4x4Mix | D5: B | E5: House of Medici | F5: REALL | G5: 1 | H5: 46186 | I5: 0.39097222 | P5: EFSA
C6: 4x4Mix | D6: A | E6: EFSA 6 | F6: Horizon setters | G6: 2 | H6: 46186 | I6: 0.39097222 | P6: EMA
C7: 4x4Mix | D7: B | E7: Dandy Dandelions | F7: REALL | G7: 2 | H7: 46186 | I7: 0.40694444 | P7: EUAA
C8: 4x4Mix | D8: A | E8: EUIPO 5 | F8: Horizon setters | G8: 3 | H8: 46186 | I8: 0.42291667 | P8: EUIPO
C9: 2x2 Mix | D9: E | E9: EUROPOL MIX | F9: Sandstormers | G9: 3 | H9: 46186 | I9: 0.64652778 | P9: EUROJUST
C10: 2x2 Mix | D10: F | E10: BBB | F10: Sandbox players | G10: 4 | H10: 46186 | I10: 0.64652778 | P10: EUROPOL
C11: 2x2 Mix | D11: F | E11: Volare oooh | F11: BBB | G11: 2 | H11: 46186 | I11: 0.6625 | P11: FRONTEX
C12: 2x2 Mix | D12: E | E12: EFSA 4 | F12: Sandstormers | G12: 3 | H12: 46186 | I12: 0.69444444 | P12: JRC
C13: 2x2 Mix | D13: F | E13: EFSA 5 | F13: BBB | G13: 2 | H13: 46186 | I13: 0.71041667 | P13: REA
C14: 2x2 Mix | D14: E | E14: Jellybeans | F14: Sandstormers | G14: 1 | H14: 46186 | I14: 0.75833333

Sheet Standings
A2: 2x2 MIX
A4: Group A | B4: Games played | C4: Wins | D4: Tied | E4: Losses | F4: Points won | G4: Points lost | H4: Score | I4: Points quotient
A5: =+'2x2 MIX'!A34 -> EUIPO 3 | B5: {=SUMPRODUCT(--('2x2 MIX'!C$43:C$82 = Standings!A5),--('2x2 MIX'!I$43:I$82<>""))+SUMPRODUCT(--('2x2 MIX'!D$43:D$82 = Standings!A5),--('2x2 MIX'!I$43:I$82<>""))} -> 0 | C5: {=SUMPRODUCT(--('2x2 MIX'!C$43:C$82 = Standings!A5),--('2x2 MIX'!I$43:I$82>'2x2 MIX'!J$43:J$82))+SUMPRODUCT(--('2x2 MIX'!D$43:D$82 = Standings!A5),--('2x2 MIX'!I$43:I$82<'2x2 MIX'!J$43:J$82))} -> 0 | D5: =+B5-C5-E5 -> 0 | E5: {=SUMPRODUCT(--('2x2 MIX'!C$43:C$82 = Standings!A5),--('2x2 MIX'!I$43:I$82<'2x2 MIX'!J$43:J$82))+SUMPRODUCT(--('2x2 MIX'!D$43:D$82 = Standings!A5),--('2x2 MIX'!I$43:I$82>'2x2 MIX'!J$43:J$82))} -> 0 | F5: =+SUMIFS('2x2 MIX'!I$43:J$82,'2x2 MIX'!C$43:D$82,Standings!A5) -> 0 | G5: {=SUMPRODUCT(--('2x2 MIX'!C$43:C$82=Standings!A5),'2x2 MIX'!J$43:J$82)+SUMPRODUCT(--('2x2 MIX'!D$43:D$82=Standings!A5),'2x2 MIX'!I$43:I$82)} -> 0 | H5: =0.75*(C5*2+D5*1) -> 0 | I5: =+F5/G5 -> #DIV/0!
A6: =+'2x2 MIX'!A35 -> Paddington | B6: {=SUMPRODUCT(--('2x2 MIX'!C$43:C$82 = Standings!A6),--('2x2 MIX'!I$43:I$82<>""))+SUMPRODUCT(--('2x2 MIX'!D$43:D$82 = Standings!A6),--('2x2 MIX'!I$43:I$82<>""))} -> 0 | C6: {=SUMPRODUCT(--('2x2 MIX'!C$43:C$82 = Standings!A6),--('2x2 MIX'!I$43:I$82>'2x2 MIX'!J$43:J$82))+SUMPRODUCT(--('2x2 MIX'!D$43:D$82 = Standings!A6),--('2x2 MIX'!I$43:I$82<'2x2 MIX'!J$43:J$82))} -> 0 | D6: =+B6-C6-E6 -> 0 | E6: {=SUMPRODUCT(--('2x2 MIX'!C$43:C$82 = Standings!A6),--('2x2 MIX'!I$43:I$82<'2x2 MIX'!J$43:J$82))+SUMPRODUCT(--('2x2 MIX'!D$43:D$82 = Standings!A6),--('2x2 MIX'!I$43:I$82>'2x2 MIX'!J$43:J$82))} -> 0 | F6: =+SUMIFS('2x2 MIX'!I$43:J$82,'2x2 MIX'!C$43:D$82,Standings!A6) -> 0 | G6: {=SUMPRODUCT(--('2x2 MIX'!C$43:C$82=Standings!A6),'2x2 MIX'!J$43:J$82)+SUMPRODUCT(--('2x2 MIX'!D$43:D$82=Standings!A6),'2x2 MIX'!I$43:I$82)} -> 0 | H6: =0.75*(C6*2+D6*1) -> 0 | I6: =+F6/G6 -> #DIV/0!
A7: =+'2x2 MIX'!A36 -> Ooh la la | B7: {=SUMPRODUCT(--('2x2 MIX'!C$43:C$82 = Standings!A7),--('2x2 MIX'!I$43:I$82<>""))+SUMPRODUCT(--('2x2 MIX'!D$43:D$82 = Standings!A7),--('2x2 MIX'!I$43:I$82<>""))} -> 0 | C7: {=SUMPRODUCT(--('2x2 MIX'!C$43:C$82 = Standings!A7),--('2x2 MIX'!I$43:I$82>'2x2 MIX'!J$43:J$82))+SUMPRODUCT(--('2x2 MIX'!D$43:D$82 = Standings!A7),--('2x2 MIX'!I$43:I$82<'2x2 MIX'!J$43:J$82))} -> 0 | D7: =+B7-C7-E7 -> 0 | E7: {=SUMPRODUCT(--('2x2 MIX'!C$43:C$82 = Standings!A7),--('2x2 MIX'!I$43:I$82<'2x2 MIX'!J$43:J$82))+SUMPRODUCT(--('2x2 MIX'!D$43:D$82 = Standings!A7),--('2x2 MIX'!I$43:I$82>'2x2 MIX'!J$43:J$82))} -> 0 | F7: =+SUMIFS('2x2 MIX'!I$43:J$82,'2x2 MIX'!C$43:D$82,Standings!A7) -> 0 | G7: {=SUMPRODUCT(--('2x2 MIX'!C$43:C$82=Standings!A7),'2x2 MIX'!J$43:J$82)+SUMPRODUCT(--('2x2 MIX'!D$43:D$82=Standings!A7),'2x2 MIX'!I$43:I$82)} -> 0 | H7: =0.75*(C7*2+D7*1) -> 0 | I7: =+F7/G7 -> #DIV/0!
A8: =+'2x2 MIX'!A37 -> Se non spigoli non vale | B8: {=SUMPRODUCT(--('2x2 MIX'!C$43:C$82 = Standings!A8),--('2x2 MIX'!I$43:I$82<>""))+SUMPRODUCT(--('2x2 MIX'!D$43:D$82 = Standings!A8),--('2x2 MIX'!I$43:I$82<>""))} -> 0 | C8: {=SUMPRODUCT(--('2x2 MIX'!C$43:C$82 = Standings!A8),--('2x2 MIX'!I$43:I$82>'2x2 MIX'!J$43:J$82))+SUMPRODUCT(--('2x2 MIX'!D$43:D$82 = Standings!A8),--('2x2 MIX'!I$43:I$82<'2x2 MIX'!J$43:J$82))} -> 0 | D8: =+B8-C8-E8 -> 0 | E8: {=SUMPRODUCT(--('2x2 MIX'!C$43:C$82 = Standings!A8),--('2x2 MIX'!I$43:I$82<'2x2 MIX'!J$43:J$82))+SUMPRODUCT(--('2x2 MIX'!D$43:D$82 = Standings!A8),--('2x2 MIX'!I$43:I$82>'2x2 MIX'!J$43:J$82))} -> 0 | F8: =+SUMIFS('2x2 MIX'!I$43:J$82,'2x2 MIX'!C$43:D$82,Standings!A8) -> 0 | G8: {=SUMPRODUCT(--('2x2 MIX'!C$43:C$82=Standings!A8),'2x2 MIX'!J$43:J$82)+SUMPRODUCT(--('2x2 MIX'!D$43:D$82=Standings!A8),'2x2 MIX'!I$43:I$82)} -> 0 | H8: =0.75*(C8*2+D8*1) -> 0 | I8: =+F8/G8 -> #DIV/0!
A9: =+'2x2 MIX'!A38 -> ECDC | B9: {=SUMPRODUCT(--('2x2 MIX'!C$43:C$82 = Standings!A9),--('2x2 MIX'!I$43:I$82<>""))+SUMPRODUCT(--('2x2 MIX'!D$43:D$82 = Standings!A9),--('2x2 MIX'!I$43:I$82<>""))} -> 0 | C9: {=SUMPRODUCT(--('2x2 MIX'!C$43:C$82 = Standings!A9),--('2x2 MIX'!I$43:I$82>'2x2 MIX'!J$43:J$82))+SUMPRODUCT(--('2x2 MIX'!D$43:D$82 = Standings!A9),--('2x2 MIX'!I$43:I$82<'2x2 MIX'!J$43:J$82))} -> 0 | D9: =+B9-C9-E9 -> 0 | E9: {=SUMPRODUCT(--('2x2 MIX'!C$43:C$82 = Standings!A9),--('2x2 MIX'!I$43:I$82<'2x2 MIX'!J$43:J$82))+SUMPRODUCT(--('2x2 MIX'!D$43:D$82 = Standings!A9),--('2x2 MIX'!I$43:I$82>'2x2 MIX'!J$43:J$82))} -> 0 | F9: =+SUMIFS('2x2 MIX'!I$43:J$82,'2x2 MIX'!C$43:D$82,Standings!A9) -> 0 | G9: {=SUMPRODUCT(--('2x2 MIX'!C$43:C$82=Standings!A9),'2x2 MIX'!J$43:J$82)+SUMPRODUCT(--('2x2 MIX'!D$43:D$82=Standings!A9),'2x2 MIX'!I$43:I$82)} -> 0 | H9: =0.75*(C9*2+D9*1) -> 0 | I9: =+F9/G9 -> #DIV/0!
A11: Group B | B11: Games played | C11: Wins | D11: Tied | E11: Losses | F11: Points won | G11: Points lost | H11: Score | I11: Points quotient
A12: =+'2x2 MIX'!B34 -> EUIPO 4 | B12: {=SUMPRODUCT(--('2x2 MIX'!C$43:C$82 = Standings!A12),--('2x2 MIX'!I$43:I$82<>""))+SUMPRODUCT(--('2x2 MIX'!D$43:D$82 = Standings!A12),--('2x2 MIX'!I$43:I$82<>""))} -> 0 | C12: {=SUMPRODUCT(--('2x2 MIX'!C$43:C$82 = Standings!A12),--('2x2 MIX'!I$43:I$82>'2x2 MIX'!J$43:J$82))+SUMPRODUCT(--('2x2 MIX'!D$43:D$82 = Standings!A12),--('2x2 MIX'!I$43:I$82<'2x2 MIX'!J$43:J$82))} -> 0 | D12: =+B12-C12-E12 -> 0 | E12: {=SUMPRODUCT(--('2x2 MIX'!C$43:C$82 = Standings!A12),--('2x2 MIX'!I$43:I$82<'2x2 MIX'!J$43:J$82))+SUMPRODUCT(--('2x2 MIX'!D$43:D$82 = Standings!A12),--('2x2 MIX'!I$43:I$82>'2x2 MIX'!J$43:J$82))} -> 0 | F12: =+SUMIFS('2x2 MIX'!I$43:J$82,'2x2 MIX'!C$43:D$82,Standings!A12) -> 0 | G12: {=SUMPRODUCT(--('2x2 MIX'!C$43:C$82=Standings!A12),'2x2 MIX'!J$43:J$82)+SUMPRODUCT(--('2x2 MIX'!D$43:D$82=Standings!A12),'2x2 MIX'!I$43:I$82)} -> 0 | H12: =+C12*2+D12*1 -> 0 | I12: =+F12/G12 -> #DIV/0!
A13: =+'2x2 MIX'!B35 -> The Lambrusco Paradox | B13: {=SUMPRODUCT(--('2x2 MIX'!C$43:C$82 = Standings!A13),--('2x2 MIX'!I$43:I$82<>""))+SUMPRODUCT(--('2x2 MIX'!D$43:D$82 = Standings!A13),--('2x2 MIX'!I$43:I$82<>""))} -> 0 | C13: {=SUMPRODUCT(--('2x2 MIX'!C$43:C$82 = Standings!A13),--('2x2 MIX'!I$43:I$82>'2x2 MIX'!J$43:J$82))+SUMPRODUCT(--('2x2 MIX'!D$43:D$82 = Standings!A13),--('2x2 MIX'!I$43:I$82<'2x2 MIX'!J$43:J$82))} -> 0 | D13: =+B13-C13-E13 -> 0 | E13: {=SUMPRODUCT(--('2x2 MIX'!C$43:C$82 = Standings!A13),--('2x2 MIX'!I$43:I$82<'2x2 MIX'!J$43:J$82))+SUMPRODUCT(--('2x2 MIX'!D$43:D$82 = Standings!A13),--('2x2 MIX'!I$43:I$82>'2x2 MIX'!J$43:J$82))} -> 0 | F13: =+SUMIFS('2x2 MIX'!I$43:J$82,'2x2 MIX'!C$43:D$82,Standings!A13) -> 0 | G13: {=SUMPRODUCT(--('2x2 MIX'!C$43:C$82=Standings!A13),'2x2 MIX'!J$43:J$82)+SUMPRODUCT(--('2x2 MIX'!D$43:D$82=Standings!A13),'2x2 MIX'!I$43:I$82)} -> 0 | H13: =+C13*2+D13*1 -> 0 | I13: =+F13/G13 -> #DIV/0!
A14: =+'2x2 MIX'!B36 -> Balkan Beach Ballers | B14: {=SUMPRODUCT(--('2x2 MIX'!C$43:C$82 = Standings!A14),--('2x2 MIX'!I$43:I$82<>""))+SUMPRODUCT(--('2x2 MIX'!D$43:D$82 = Standings!A14),--('2x2 MIX'!I$43:I$82<>""))} -> 0 | C14: {=SUMPRODUCT(--('2x2 MIX'!C$43:C$82 = Standings!A14),--('2x2 MIX'!I$43:I$82>'2x2 MIX'!J$43:J$82))+SUMPRODUCT(--('2x2 MIX'!D$43:D$82 = Standings!A14),--('2x2 MIX'!I$43:I$82<'2x2 MIX'!J$43:J$82))} -> 0 | D14: =+B14-C14-E14 -> 0 | E14: {=SUMPRODUCT(--('2x2 MIX'!C$43:C$82 = Standings!A14),--('2x2 MIX'!I$43:I$82<'2x2 MIX'!J$43:J$82))+SUMPRODUCT(--('2x2 MIX'!D$43:D$82 = Standings!A14),--('2x2 MIX'!I$43:I$82>'2x2 MIX'!J$43:J$82))} -> 0 | F14: =+SUMIFS('2x2 MIX'!I$43:J$82,'2x2 MIX'!C$43:D$82,Standings!A14) -> 0 | G14: {=SUMPRODUCT(--('2x2 MIX'!C$43:C$82=Standings!A14),'2x2 MIX'!J$43:J$82)+SUMPRODUCT(--('2x2 MIX'!D$43:D$82=Standings!A14),'2x2 MIX'!I$43:I$82)} -> 0 | H14: =+C14*2+D14*1 -> 0 | I14: =+F14/G14 -> #DIV/0!
A15: =+'2x2 MIX'!B37 -> JRC Energy dense | B15: {=SUMPRODUCT(--('2x2 MIX'!C$43:C$82 = Standings!A15),--('2x2 MIX'!I$43:I$82<>""))+SUMPRODUCT(--('2x2 MIX'!D$43:D$82 = Standings!A15),--('2x2 MIX'!I$43:I$82<>""))} -> 0 | C15: {=SUMPRODUCT(--('2x2 MIX'!C$43:C$82 = Standings!A15),--('2x2 MIX'!I$43:I$82>'2x2 MIX'!J$43:J$82))+SUMPRODUCT(--('2x2 MIX'!D$43:D$82 = Standings!A15),--('2x2 MIX'!I$43:I$82<'2x2 MIX'!J$43:J$82))} -> 0 | D15: =+B15-C15-E15 -> 0 | E15: {=SUMPRODUCT(--('2x2 MIX'!C$43:C$82 = Standings!A15),--('2x2 MIX'!I$43:I$82<'2x2 MIX'!J$43:J$82))+SUMPRODUCT(--('2x2 MIX'!D$43:D$82 = Standings!A15),--('2x2 MIX'!I$43:I$82>'2x2 MIX'!J$43:J$82))} -> 0 | F15: =+SUMIFS('2x2 MIX'!I$43:J$82,'2x2 MIX'!C$43:D$82,Standings!A15) -> 0 | G15: {=SUMPRODUCT(--('2x2 MIX'!C$43:C$82=Standings!A15),'2x2 MIX'!J$43:J$82)+SUMPRODUCT(--('2x2 MIX'!D$43:D$82=Standings!A15),'2x2 MIX'!I$43:I$82)} -> 0 | H15: =+C15*2+D15*1 -> 0 | I15: =+F15/G15 -> #DIV/0!
A17: Group C | B17: Games played | C17: Wins | D17: Tied | E17: Losses | F17: Points won | G17: Points lost | H17: Score | I17: Points quotient
A18: =+'2x2 MIX'!C34 -> Copacabana | B18: {=SUMPRODUCT(--('2x2 MIX'!C$43:C$82 = Standings!A18),--('2x2 MIX'!I$43:I$82<>""))+SUMPRODUCT(--('2x2 MIX'!D$43:D$82 = Standings!A18),--('2x2 MIX'!I$43:I$82<>""))} -> 0 | C18: {=SUMPRODUCT(--('2x2 MIX'!C$43:C$82 = Standings!A18),--('2x2 MIX'!I$43:I$82>'2x2 MIX'!J$43:J$82))+SUMPRODUCT(--('2x2 MIX'!D$43:D$82 = Standings!A18),--('2x2 MIX'!I$43:I$82<'2x2 MIX'!J$43:J$82))} -> 0 | D18: =+B18-C18-E18 -> 0 | E18: {=SUMPRODUCT(--('2x2 MIX'!C$43:C$82 = Standings!A18),--('2x2 MIX'!I$43:I$82<'2x2 MIX'!J$43:J$82))+SUMPRODUCT(--('2x2 MIX'!D$43:D$82 = Standings!A18),--('2x2 MIX'!I$43:I$82>'2x2 MIX'!J$43:J$82))} -> 0 | F18: =+SUMIFS('2x2 MIX'!I$43:J$82,'2x2 MIX'!C$43:D$82,Standings!A18) -> 0 | G18: {=SUMPRODUCT(--('2x2 MIX'!C$43:C$82=Standings!A18),'2x2 MIX'!J$43:J$82)+SUMPRODUCT(--('2x2 MIX'!D$43:D$82=Standings!A18),'2x2 MIX'!I$43:I$82)} -> 0 | H18: =+C18*2+D18*1 -> 0 | I18: =+F18/G18 -> #DIV/0!
A19: =+'2x2 MIX'!C35 -> From Tokyo to The Hague | B19: {=SUMPRODUCT(--('2x2 MIX'!C$43:C$82 = Standings!A19),--('2x2 MIX'!I$43:I$82<>""))+SUMPRODUCT(--('2x2 MIX'!D$43:D$82 = Standings!A19),--('2x2 MIX'!I$43:I$82<>""))} -> 0 | C19: {=SUMPRODUCT(--('2x2 MIX'!C$43:C$82 = Standings!A19),--('2x2 MIX'!I$43:I$82>'2x2 MIX'!J$43:J$82))+SUMPRODUCT(--('2x2 MIX'!D$43:D$82 = Standings!A19),--('2x2 MIX'!I$43:I$82<'2x2 MIX'!J$43:J$82))} -> 0 | D19: =+B19-C19-E19 -> 0 | E19: {=SUMPRODUCT(--('2x2 MIX'!C$43:C$82 = Standings!A19),--('2x2 MIX'!I$43:I$82<'2x2 MIX'!J$43:J$82))+SUMPRODUCT(--('2x2 MIX'!D$43:D$82 = Standings!A19),--('2x2 MIX'!I$43:I$82>'2x2 MIX'!J$43:J$82))} -> 0 | F19: =+SUMIFS('2x2 MIX'!I$43:J$82,'2x2 MIX'!C$43:D$82,Standings!A19) -> 0 | G19: {=SUMPRODUCT(--('2x2 MIX'!C$43:C$82=Standings!A19),'2x2 MIX'!J$43:J$82)+SUMPRODUCT(--('2x2 MIX'!D$43:D$82=Standings!A19),'2x2 MIX'!I$43:I$82)} -> 0 | H19: =+C19*2+D19*1 -> 0 | I19: =+F19/G19 -> #DIV/0!
A20: =+'2x2 MIX'!C36 -> Mdina Defenders | B20: {=SUMPRODUCT(--('2x2 MIX'!C$43:C$82 = Standings!A20),--('2x2 MIX'!I$43:I$82<>""))+SUMPRODUCT(--('2x2 MIX'!D$43:D$82 = Standings!A20),--('2x2 MIX'!I$43:I$82<>""))} -> 0 | C20: {=SUMPRODUCT(--('2x2 MIX'!C$43:C$82 = Standings!A20),--('2x2 MIX'!I$43:I$82>'2x2 MIX'!J$43:J$82))+SUMPRODUCT(--('2x2 MIX'!D$43:D$82 = Standings!A20),--('2x2 MIX'!I$43:I$82<'2x2 MIX'!J$43:J$82))} -> 0 | D20: =+B20-C20-E20 -> 0 | E20: {=SUMPRODUCT(--('2x2 MIX'!C$43:C$82 = Standings!A20),--('2x2 MIX'!I$43:I$82<'2x2 MIX'!J$43:J$82))+SUMPRODUCT(--('2x2 MIX'!D$43:D$82 = Standings!A20),--('2x2 MIX'!I$43:I$82>'2x2 MIX'!J$43:J$82))} -> 0 | F20: =+SUMIFS('2x2 MIX'!I$43:J$82,'2x2 MIX'!C$43:D$82,Standings!A20) -> 0 | G20: {=SUMPRODUCT(--('2x2 MIX'!C$43:C$82=Standings!A20),'2x2 MIX'!J$43:J$82)+SUMPRODUCT(--('2x2 MIX'!D$43:D$82=Standings!A20),'2x2 MIX'!I$43:I$82)} -> 0 | H20: =+C20*2+D20*1 -> 0 | I20: =+F20/G20 -> #DIV/0!
A21: =+'2x2 MIX'!C37 -> Gianmarcoooo | B21: {=SUMPRODUCT(--('2x2 MIX'!C$43:C$82 = Standings!A21),--('2x2 MIX'!I$43:I$82<>""))+SUMPRODUCT(--('2x2 MIX'!D$43:D$82 = Standings!A21),--('2x2 MIX'!I$43:I$82<>""))} -> 0 | C21: {=SUMPRODUCT(--('2x2 MIX'!C$43:C$82 = Standings!A21),--('2x2 MIX'!I$43:I$82>'2x2 MIX'!J$43:J$82))+SUMPRODUCT(--('2x2 MIX'!D$43:D$82 = Standings!A21),--('2x2 MIX'!I$43:I$82<'2x2 MIX'!J$43:J$82))} -> 0 | D21: =+B21-C21-E21 -> 0 | E21: {=SUMPRODUCT(--('2x2 MIX'!C$43:C$82 = Standings!A21),--('2x2 MIX'!I$43:I$82<'2x2 MIX'!J$43:J$82))+SUMPRODUCT(--('2x2 MIX'!D$43:D$82 = Standings!A21),--('2x2 MIX'!I$43:I$82>'2x2 MIX'!J$43:J$82))} -> 0 | F21: =+SUMIFS('2x2 MIX'!I$43:J$82,'2x2 MIX'!C$43:D$82,Standings!A21) -> 0 | G21: {=SUMPRODUCT(--('2x2 MIX'!C$43:C$82=Standings!A21),'2x2 MIX'!J$43:J$82)+SUMPRODUCT(--('2x2 MIX'!D$43:D$82=Standings!A21),'2x2 MIX'!I$43:I$82)} -> 0 | H21: =+C21*2+D21*1 -> 0 | I21: =+F21/G21 -> #DIV/0!
A23: Group D | B23: Games played | C23: Wins | D23: Tied | E23: Losses | F23: Points won | G23: Points lost | H23: Score | I23: Points quotient
